Workbook

Sheet Industry & Competitor Analysis
A1: Rasio-Rasio Keuangan Perusahaan Pupuk di Indonesia
B3: Rasio Keuangan Tahunan 2021-2025 (Berdasarkan 3 Perusahaan Pupuk di Indonesia) | I3: Rasio Keuangan 2021-2025 (Berdasarkan 4 Perusahaan Pupuk di Indonesia) | P3: Rasio Keuangan 2021-2025 (Berdasarkan 4 Perusahaan Pupuk di Indonesia) | W3: Rasio Keuangan 2021-2025 PT Pupuk Kalimatan Timur | AD3: Rasio Keuangan 2021-2025 PT Pupuk Kalimatan Timur | AK3: Rasio Keuangan 2021-2025 PT Pupuk Kalimatan Timur | AR3: Rasio Keuangan 2021-2025 PT Saraswati Anugerah Makmur Tbk | AY3: Rasio Keuangan 2021-2025 PT Saraswati Anugerah Makmur Tbk | BF3: Rasio Keuangan 2021-2025 PT Saraswati Anugerah Makmur Tbk | BM3: Rasio Keuangan 2021-2025 PT Delta Giri Wacana Tbk | BT3: Rasio Keuangan 2021-2025 PT Delta Giri Wacana Tbk | CA3: Rasio Keuangan 2021-2025 PT Delta Giri Wacana Tbk | CH3: Rasio Keuangan 2021-2025 PT Nusa Palapa Gemilang Tbk | CO3: Rasio Keuangan 2021-2025 PT Nusa Palapa Gemilang Tbk | CV3: Rasio Keuangan 2021-2025 PT Nusa Palapa Gemilang Tbk
B4: Metric | C4: Min | D4: Q1 / Lower Benchmark | E4: Median | F4: Q3 / Upper Benchmark | G4: Max | I4: Metric | J4: Min | K4: Q1 / Lower Benchmark | L4: Median | M4: Q3 / Upper Benchmark | N4: Max | P4: Metric | Q4: Min | R4: Q1 / Lower Benchmark | S4: Median | T4: Q3 / Upper Benchmark | U4: Max | W4: Metric | X4: Min | Y4: Q1 / Lower Benchmark | Z4: Median | AA4: Q3 / Upper Benchmark | AB4: Max | AD4: Metric | AE4: Min | AF4: Q1 / Lower Benchmark | AG4: Median | AH4: Q3 / Upper Benchmark | AI4: Max | AK4: Metric | AL4: Min | AM4: Q1 / Lower Benchmark | AN4: Median | AO4: Q3 / Upper Benchmark | AP4: Max | AR4: Metric | AS4: Min | AT4: Q1 / Lower Benchmark | AU4: Median | AV4: Q3 / Upper Benchmark | AW4: Max | AY4: Metric | AZ4: Min | BA4: Q1 / Lower Benchmark | BB4: Median | BC4: Q3 / Upper Benchmark | BD4: Max | BF4: Metric | BG4: Min | BH4: Q1 / Lower Benchmark | BI4: Median | BJ4: Q3 / Upper Benchmark | BK4: Max | BM4: Metric | BN4: Min | BO4: Q1 / Lower Benchmark | BP4: Median | BQ4: Q3 / Upper Benchmark | BR4: Max | BT4: Metric | BU4: Min | BV4: Q1 / Lower Benchmark | BW4: Median | BX4: Q3 / Upper Benchmark | BY4: Max | CA4: Metric | CB4: Min | CC4: Q1 / Lower Benchmark | CD4: Median | CE4: Q3 / Upper Benchmark | CF4: Max | CH4: Metric | CI4: Min | CJ4: Q1 / Lower Benchmark | CK4: Median | CL4: Q3 / Upper Benchmark | CM4: Max | CO4: Metric | CP4: Min | CQ4: Q1 / Lower Benchmark | CR4: Median | CS4: Q3 / Upper Benchmark | CT4: Max | CV4: Metric | CW4: Min | CX4: Q1 / Lower Benchmark | CY4: Median | CZ4: Q3 / Upper Benchmark | DA4: Max
B5: Gross Profit Margin (GPM) | C5: {=MIN(TOCOL(C15:G17,1))} -> -0.0077 | D5: {=_xlfn.QUARTILE.INC(TOCOL(C15:G17,1),1)} -> 0.2194 | E5: {=MEDIAN(TOCOL(C15:G17,1))} -> 0.2402 | F5: {=_xlfn.QUARTILE.INC(TOCOL(C15:G17,1),3)} -> 0.24855 | G5: {=MAX(TOCOL(C14:G17,1))} -> 0.2766 | I5: Current Ratio | J5: {=MIN(TOCOL(C42:G44,1))} -> 0.83 | K5: {=_xlfn.QUARTILE.INC(TOCOL(C42:G44,1),1)} -> 1.185 | L5: {=MEDIAN(TOCOL(C42:G44,1))} -> 1.39 | M5: {=_xlfn.QUARTILE.INC(TOCOL(C42:G44,1),3)} -> 2.015 | N5: {=MAX(TOCOL(C42:G44,1))} -> 5.18 | P5: DIO | Q5: {=MIN(TOCOL(C56:F59,1))} -> #REF! | R5: {=_xlfn.QUARTILE.INC(TOCOL(C56:F59,1),1)} -> #REF! | S5: {=MEDIAN(TOCOL(C56:F59,1))} -> #REF! | T5: {=_xlfn.QUARTILE.INC(TOCOL(C56:F59,1),3)} -> #REF! | U5: {=MAX(TOCOL(C56:F59,1))} -> #REF! | W5: Gross Profit Margin (GPM) | X5: =MIN(C14:G14) -> 0 | Y5: {=_xlfn.QUARTILE.INC(TOCOL(C14:G14,1),1)} -> #NUM! | Z5: {=MEDIAN(TOCOL(C14:G14,1))} -> #NUM! | AA5: {=_xlfn.QUARTILE.INC(TOCOL(C14:G14,1),3)} -> #NUM! | AB5: {=MAX(TOCOL(C14:G14,1))} -> 0 | AD5: Current Ratio | AE5: {=MIN(TOCOL(C41:G41,1))} -> 163 | AF5: {=_xlfn.QUARTILE.INC(TOCOL(C41:G41,1),1)} -> 204 | AG5: {=MEDIAN(TOCOL(C41:G41,1))} -> 245 | AH5: {=_xlfn.QUARTILE.INC(TOCOL(C41:G41,1),3)} -> 302 | AI5: {=MAX(TOCOL(C41:G41,1))} -> 310 | AK5: DIO | AL5: {=MIN(TOCOL(C56:G56,1))} -> 163 | AM5: {=_xlfn.QUARTILE.INC(TOCOL(C56:G56,1),1)} -> 204 | AN5: {=MEDIAN(TOCOL(C56:G56,1))} -> 245 | AO5: {=_xlfn.QUARTILE.INC(TOCOL(C56:G56,1),3)} -> 302 | AP5: {=MAX(TOCOL(C56:G56,1))} -> 310 | AR5: Gross Profit Margin (GPM) | AS5: {=MIN(TOCOL(C15:G15,1))} -> 0.2125 | AT5: {=_xlfn.QUARTILE.INC(TOCOL(C15:G15,1),1)} -> 0.2402 | AU5: {=MEDIAN(TOCOL(C15:G15,1))} -> 0.2452 | AV5: {=_xlfn.QUARTILE.INC(TOCOL(C15:G15,1),3)} -> 0.246 | AW5: {=MAX(TOCOL(C15:G15,1))} -> 0.2559 | AY5: Current Ratio | AZ5: {=MIN(TOCOL(C42:G42,1))} -> 1.39 | BA5: {=_xlfn.QUARTILE.INC(TOCOL(C42:G42,1),1)} -> 1.6 | BB5: {=MEDIAN(TOCOL(C42:G42,1))} -> 1.76 | BC5: {=_xlfn.QUARTILE.INC(TOCOL(C42:G42,1),3)} -> 1.98 | BD5: {=MAX(TOCOL(C42:G42,1))} -> 2.05 | BF5: DIO | BG5: {=MIN(TOCOL(C57:G57,1))} -> #REF! | BH5: {=_xlfn.QUARTILE.INC(TOCOL(C57:G57,1),1)} -> #REF! | BI5: {=MEDIAN(TOCOL(C57:G57,1))} -> #REF! | BJ5: {=_xlfn.QUARTILE.INC(TOCOL(C57:G57,1),3)} -> #REF! | BK5: {=MAX(TOCOL(C57:G57,1))} -> #REF! | BM5: Gross Profit Margin (GPM) | BN5: {=MIN(TOCOL(C16:G16,1))} -> 0.2263 | BO5: {=_xlfn.QUARTILE.INC(TOCOL(C16:G16,1),1)} -> 0.2321 | BP5: {=MEDIAN(TOCOL(C16:G16,1))} -> 0.2511 | BQ5: {=_xlfn.QUARTILE.INC(TOCOL(C16:G16,1),3)} -> 0.2675 | BR5: {=MAX(TOCOL(C16:G16,1))} -> 0.2766 | BT5: Current Ratio | BU5: {=MIN(TOCOL(C43:G43,1))} -> 1.02 | BV5: {=_xlfn.QUARTILE.INC(TOCOL(C43:G43,1),1)} -> 1.14 | BW5: {=MEDIAN(TOCOL(C43:G43,1))} -> 1.15 | BX5: {=_xlfn.QUARTILE.INC(TOCOL(C43:G43,1),3)} -> 1.22 | BY5: {=MAX(TOCOL(C43:G43,1))} -> 1.27 | CA5: DIO | CB5: {=MIN(TOCOL(C58:G58,1))} -> #REF! | CC5: {=_xlfn.QUARTILE.INC(TOCOL(C58:G58,1),1)} -> #REF! | CD5: {=MEDIAN(TOCOL(C58:G58,1))} -> #REF! | CE5: {=_xlfn.QUARTILE.INC(TOCOL(C58:G58,1),3)} -> #REF! | CF5: {=MAX(TOCOL(C58:G58,1))} -> #REF! | CH5: Gross Profit Margin (GPM) | CI5: {=MIN(TOCOL(C17:G17,1))} -> -0.0077 | CJ5: {=_xlfn.QUARTILE.INC(TOCOL(C17:G17,1),1)} -> 0.0318 | CK5: {=MEDIAN(TOCOL(C17:G17,1))} -> 0.1629 | CL5: {=_xlfn.QUARTILE.INC(TOCOL(C17:G17,1),3)} -> 0.2401 | CM5: {=MAX(TOCOL(C17:G17,1))} -> 0.2453 | CO5: Current Ratio | CP5: {=MIN(TOCOL(C44:G44,1))} -> 0.83 | CQ5: {=_xlfn.QUARTILE.INC(TOCOL(C44:G44,1),1)} -> 1.26 | CR5: {=MEDIAN(TOCOL(C44:G44,1))} -> 2.2 | CS5: {=_xlfn.QUARTILE.INC(TOCOL(C44:G44,1),3)} -> 2.99 | CT5: {=MAX(TOCOL(C44:G44,1))} -> 5.18 | CV5: DIO | CW5: {=MIN(TOCOL(C59:G59,1))} -> #REF! | CX5: {=_xlfn.QUARTILE.INC(TOCOL(C59:G59,1),1)} -> #REF! | CY5: {=MEDIAN(TOCOL(C59:G59,1))} -> #REF! | CZ5: {=_xlfn.QUARTILE.INC(TOCOL(C59:G59,1),3)} -> #REF! | DA5: {=MAX(TOCOL(C59:G59,1))} -> #REF!
B6: Operating Profit Margin (OPM) | C6: {=MIN(TOCOL(H15:L17,1))} -> -0.5802 | D6: {=_xlfn.QUARTILE.INC(TOCOL(H15:L17,1),1)} -> 0.05385 | E6: {=MEDIAN(TOCOL(H15:L17,1))} -> 0.0827 | F6: {=_xlfn.QUARTILE.INC(TOCOL(H15:L17,1),3)} -> 0.112 | G6: {=MAX(TOCOL(I14:L17,1))} -> 0.1394 | I6: Quick Ratio | J6: {=MIN(TOCOL(J42:N44,1))} -> 0.47 | K6: {=_xlfn.QUARTILE.INC(TOCOL(J42:N44,1),1)} -> 0.535 | L6: {=MEDIAN(TOCOL(J42:N44,1))} -> 0.72 | M6: {=_xlfn.QUARTILE.INC(TOCOL(J42:N44,1),3)} -> 1.195 | N6: {=MAX(TOCOL(J42:N44,1))} -> 2.58 | P6: DSO | Q6: {=MIN(TOCOL(J56:M59,1))} -> #REF! | R6: {=_xlfn.QUARTILE.INC(TOCOL(J56:M59,1),1)} -> #REF! | S6: {=MEDIAN(TOCOL(J56:M59,1))} -> #REF! | T6: {=_xlfn.QUARTILE.INC(TOCOL(J56:M59,1),3)} -> #REF! | U6: {=MAX(TOCOL(J56:M59,1))} -> #REF! | W6: Operating Profit Margin (OPM) | X6: {=MIN(TOCOL(H14:L14,1))} -> 0 | Y6: {=_xlfn.QUARTILE.INC(TOCOL(H14:L14,1),1)} -> #NUM! | Z6: {=MEDIAN(TOCOL(H14:L14,1))} -> #NUM! | AA6: {=_xlfn.QUARTILE.INC(TOCOL(H14:L14,1),3)} -> #NUM! | AB6: {=MAX(TOCOL(H14:L14,1))} -> 0 | AD6: Quick Ratio | AE6: {=MIN(TOCOL(J41:N41,1))} -> 163 | AF6: {=_xlfn.QUARTILE.INC(TOCOL(J41:N41,1),1)} -> 204 | AG6: {=MEDIAN(TOCOL(J41:N41,1))} -> 245 | AH6: {=_xlfn.QUARTILE.INC(TOCOL(J41:N41,1),3)} -> 302 | AI6: {=MAX(TOCOL(J41:N41,1))} -> 310 | AK6: DSO | AL6: {=MIN(TOCOL(J56:N56,1))} -> 163 | AM6: {=_xlfn.QUARTILE.INC(TOCOL(J56:N56,1),1)} -> 204 | AN6: {=MEDIAN(TOCOL(J56:N56,1))} -> 245 | AO6: {=_xlfn.QUARTILE.INC(TOCOL(J56:N56,1),3)} -> 302 | AP6: {=MAX(TOCOL(J56:N56,1))} -> 310 | AR6: Operating Profit Margin (OPM) | AS6: {=MIN(TOCOL(H15:L15,1))} -> 0.0998 | AT6: {=_xlfn.QUARTILE.INC(TOCOL(H15:L15,1),1)} -> 0.1242 | AU6: {=MEDIAN(TOCOL(H15:L15,1))} -> 0.1299 | AV6: {=_xlfn.QUARTILE.INC(TOCOL(H15:L15,1),3)} -> 0.1352 | AW6: {=MAX(TOCOL(H15:L15,1))} -> 0.1394 | AY6: Quick Ratio | AZ6: {=MIN(TOCOL(J42:N42,1))} -> 0.47 | BA6: {=_xlfn.QUARTILE.INC(TOCOL(J42:N42,1),1)} -> 0.68 | BB6: {=MEDIAN(TOCOL(J42:N42,1))} -> 0.72 | BC6: {=_xlfn.QUARTILE.INC(TOCOL(J42:N42,1),3)} -> 1.19 | BD6: {=MAX(TOCOL(J42:N42,1))} -> 1.2 | BF6: DSO | BG6: {=MIN(TOCOL(J57:N57,1))} -> #REF! | BH6: {=_xlfn.QUARTILE.INC(TOCOL(J57:N57,1),1)} -> #REF! | BI6: {=MEDIAN(TOCOL(J57:N57,1))} -> #REF! | BJ6: {=_xlfn.QUARTILE.INC(TOCOL(J57:N57,1),3)} -> #REF! | BK6: {=MAX(TOCOL(J57:N57,1))} -> #REF! | BM6: Operating Profit Margin (OPM) | BN6: {=MIN(TOCOL(H16:L16,1))} -> 0.0344 | BO6: {=_xlfn.QUARTILE.INC(TOCOL(H16:L16,1),1)} -> 0.0726 | BP6: {=MEDIAN(TOCOL(H16:L16,1))} -> 0.0827 | BQ6: {=_xlfn.QUARTILE.INC(TOCOL(H16:L16,1),3)} -> 0.0837 | BR6: {=MAX(TOCOL(H16:L16,1))} -> 0.0969 | BT6: Quick Ratio | BU6: {=MIN(TOCOL(J43:N43,1))} -> 0.48 | BV6: {=_xlfn.QUARTILE.INC(TOCOL(J43:N43,1),1)} -> 0.51 | BW6: {=MEDIAN(TOCOL(J43:N43,1))} -> 0.52 | BX6: {=_xlfn.QUARTILE.INC(TOCOL(J43:N43,1),3)} -> 0.59 | BY6: {=MAX(TOCOL(J43:N43,1))} -> 0.85 | CA6: DSO | CB6: {=MIN(TOCOL(J58:N58,1))} -> #REF! | CC6: {=_xlfn.QUARTILE.INC(TOCOL(J58:N58,1),1)} -> #REF! | CD6: {=MEDIAN(TOCOL(J58:N58,1))} -> #REF! | CE6: {=_xlfn.QUARTILE.INC(TOCOL(J58:N58,1),3)} -> #REF! | CF6: {=MAX(TOCOL(J58:N58,1))} -> #REF! | CH6: Operating Profit Margin (OPM) | CI6: {=MIN(TOCOL(H17:L17,1))} -> -0.5802 | CJ6: {=_xlfn.QUARTILE.INC(TOCOL(H17:L17,1),1)} -> -0.2039 | CK6: {=MEDIAN(TOCOL(H17:L17,1))} -> 0.047 | CL6: {=_xlfn.QUARTILE.INC(TOCOL(H17:L17,1),3)} -> 0.0607 | CM6: {=MAX(TOCOL(H17:L17,1))} -> 0.0658 | CO6: Quick Ratio | CP6: {=MIN(TOCOL(J44:N44,1))} -> 0.55 | CQ6: {=_xlfn.QUARTILE.INC(TOCOL(J44:N44,1),1)} -> 0.83 | CR6: {=MEDIAN(TOCOL(J44:N44,1))} -> 1.39 | CS6: {=_xlfn.QUARTILE.INC(TOCOL(J44:N44,1),3)} -> 1.68 | CT6: {=MAX(TOCOL(J44:N44,1))} -> 2.58 | CV6: DSO | CW6: {=MIN(TOCOL(J59:N59,1))} -> #REF! | CX6: {=_xlfn.QUARTILE.INC(TOCOL(J59:N59,1),1)} -> #REF! | CY6: {=MEDIAN(TOCOL(J59:N59,1))} -> #REF! | CZ6: {=_xlfn.QUARTILE.INC(TOCOL(J59:N59,1),3)} -> #REF! | DA6: {=MAX(TOCOL(J59:N59,1))} -> #REF!
B7: Net Profit Margin (NPM) | C7: {=MIN(TOCOL(M15:Q17,1))} -> -0.2477 | D7: {=_xlfn.QUARTILE.INC(TOCOL(M15:Q16,1),1)} -> 0.0544 | E7: {=MEDIAN(TOCOL(N15:Q17,1))} -> 0.0688 | F7: {=_xlfn.QUARTILE.INC(TOCOL(M15:Q17,1),3)} -> 0.0868 | G7: {=MAX(TOCOL(M14:Q17,1))} -> 1.1501 | I7: Inventory Turnover | J7: {=MIN(TOCOL(C50:G52,1))} -> 0.68 | K7: {=_xlfn.QUARTILE.INC(TOCOL(C50:G52,1),1)} -> 2.195 | L7: {=MEDIAN(TOCOL(C50:G52,1))} -> 2.395 | M7: {=_xlfn.QUARTILE.INC(TOCOL(C50:G52,1),3)} -> 2.55 | N7: {=MAX(TOCOL(C50:G52,1))} -> 4.1 | P7: DPO | Q7: {=MIN(TOCOL(C63:F66,1))} -> #REF! | R7: {=_xlfn.QUARTILE.INC(TOCOL(C63:F66,1),1)} -> #REF! | S7: {=MEDIAN(TOCOL(C63:F66,1))} -> #REF! | T7: {=_xlfn.QUARTILE.INC(TOCOL(C63:F66,1),3)} -> #REF! | U7: {=MAX(TOCOL(C63:F66,1))} -> #REF! | W7: Net Profit Margin (NPM) | X7: {=MIN(TOCOL(M14:Q14,1))} -> 0 | Y7: {=_xlfn.QUARTILE.INC(TOCOL(M14:Q14,1),1)} -> #NUM! | Z7: {=MEDIAN(TOCOL(M14:Q14,1))} -> #NUM! | AA7: {=_xlfn.QUARTILE.INC(TOCOL(M14:Q14,1),3)} -> #NUM! | AB7: {=MAX(TOCOL(M14:Q14,1))} -> 0 | AD7: Inventory Turnover | AE7: {=MIN(TOCOL(C49:G49,1))} -> 163 | AF7: {=_xlfn.QUARTILE.INC(TOCOL(C49:G49,1),1)} -> 204 | AG7: {=MEDIAN(TOCOL(C49:G49,1))} -> 245 | AH7: {=_xlfn.QUARTILE.INC(TOCOL(C49:G49,1),3)} -> 302 | AI7: {=MAX(TOCOL(C49:G49,1))} -> 310 | AK7: DPO | AL7: {=MIN(TOCOL(C63:G63,1))} -> 163 | AM7: {=_xlfn.QUARTILE.INC(TOCOL(C63:G63,1),1)} -> 204 | AN7: {=MEDIAN(TOCOL(C63:G63,1))} -> 245 | AO7: {=_xlfn.QUARTILE.INC(TOCOL(C63:G63,1),3)} -> 302 | AP7: {=MAX(TOCOL(C63:G63,1))} -> 310 | AR7: Net Profit Margin (NPM) | AS7: {=MIN(TOCOL(M15:Q15,1))} -> 0.0627 | AT7: {=_xlfn.QUARTILE.INC(TOCOL(M15:Q15,1),1)} -> 0.079 | AU7: {=MEDIAN(TOCOL(M15:Q15,1))} -> 0.0893 | AV7: {=_xlfn.QUARTILE.INC(TOCOL(M15:Q15,1),3)} -> 0.0906 | AW7: {=MAX(TOCOL(M15:Q15,1))} -> 0.091 | AY7: Inventory Turnover | AZ7: {=MIN(TOCOL(C50:G50,1))} -> 2.3 | BA7: {=_xlfn.QUARTILE.INC(TOCOL(C50:G50,1),1)} -> 2.31 | BB7: {=MEDIAN(TOCOL(C50:G50,1))} -> 2.42 | BC7: {=_xlfn.QUARTILE.INC(TOCOL(C50:G50,1),3)} -> 3.37 | BD7: {=MAX(TOCOL(C50:G50,1))} -> 3.6 | BF7: DPO | BG7: {=MIN(TOCOL(C64:G64,1))} -> #REF! | BH7: {=_xlfn.QUARTILE.INC(TOCOL(C64:G64,1),1)} -> #REF! | BI7: {=MEDIAN(TOCOL(C64:G64,1))} -> #REF! | BJ7: {=_xlfn.QUARTILE.INC(TOCOL(C64:G64,1),3)} -> #REF! | BK7: {=MAX(TOCOL(C64:G64,1))} -> #REF! | BM7: Net Profit Margin (NPM) | BN7: {=MIN(TOCOL(M16:Q16,1))} -> 0.005 | BO7: {=_xlfn.QUARTILE.INC(TOCOL(M16:Q16,1),1)} -> 0.0528 | BP7: {=MEDIAN(TOCOL(M16:Q16,1))} -> 0.053 | BQ7: {=_xlfn.QUARTILE.INC(TOCOL(M16:Q16,1),3)} -> 0.0586 | BR7: {=MAX(TOCOL(M16:Q16,1))} -> 0.0843 | BT7: Inventory Turnover | BU7: {=MIN(TOCOL(C51:G51,1))} -> 2.16 | BV7: {=_xlfn.QUARTILE.INC(TOCOL(C51:G51,1),1)} -> 2.3175 | BW7: {=MEDIAN(TOCOL(C51:G51,1))} -> 2.415 | BX7: {=_xlfn.QUARTILE.INC(TOCOL(C51:G51,1),3)} -> 2.49 | BY7: {=MAX(TOCOL(C51:G51,1))} -> 2.58 | CA7: DPO | CB7: {=MIN(TOCOL(C65:G65,1))} -> #REF! | CC7: {=_xlfn.QUARTILE.INC(TOCOL(C65:G65,1),1)} -> #REF! | CD7: {=MEDIAN(TOCOL(C65:G65,1))} -> #REF! | CE7: {=_xlfn.QUARTILE.INC(TOCOL(C65:G65,1),3)} -> #REF! | CF7: {=MAX(TOCOL(C65:G65,1))} -> #REF! | CH7: Net Profit Margin (NPM) | CI7: {=MIN(TOCOL(M17:Q17,1))} -> -0.2477 | CJ7: {=_xlfn.QUARTILE.INC(TOCOL(M17:Q17,1),1)} -> 0.0122 | CK7: {=MEDIAN(TOCOL(M17:Q17,1))} -> 0.0178 | CL7: {=_xlfn.QUARTILE.INC(TOCOL(M17:Q17,1),3)} -> 0.0192 | CM7: {=MAX(TOCOL(M17:Q17,1))} -> 1.1501 | CO7: Inventory Turnover | CP7: {=MIN(TOCOL(C52:G52,1))} -> 0.68 | CQ7: {=_xlfn.QUARTILE.INC(TOCOL(C52:G52,1),1)} -> 1.29 | CR7: {=MEDIAN(TOCOL(C52:G52,1))} -> 1.87 | CS7: {=_xlfn.QUARTILE.INC(TOCOL(C52:G52,1),3)} -> 2.42 | CT7: {=MAX(TOCOL(C52:G52,1))} -> 4.1 | CV7: DPO | CW7: {=MIN(TOCOL(C66:G66,1))} -> #REF! | CX7: {=_xlfn.QUARTILE.INC(TOCOL(C66:G66,1),1)} -> #REF! | CY7: {=MEDIAN(TOCOL(C66:G66,1))} -> #REF! | CZ7: {=_xlfn.QUARTILE.INC(TOCOL(C66:G66,1),3)} -> #REF! | DA7: {=MAX(TOCOL(C66:G66,1))} -> #REF!
B8: EBITDA Margin | C8: {=MIN(TOCOL(C78:G80,1))} -> -0.5108 | D8: {=_xlfn.QUARTILE.INC(TOCOL(C78:G80,1),1)} -> 0.07305 | E8: {=MEDIAN(TOCOL(C78:G80,1))} -> 0.0896 | F8: {=_xlfn.QUARTILE.INC(TOCOL(C78:G80,1),3)} -> 0.12095 | G8: {=MAX(TOCOL(C77:G80,1))} -> 55.01 | I8: Debt to Equity Ratio (DER) | J8: {=MIN(TOCOL(J50:N52,1))} -> 0.12 | K8: {=_xlfn.QUARTILE.INC(TOCOL(J50:N52,1),1)} -> 0.5 | L8: {=MEDIAN(TOCOL(J50:N52,1))} -> 0.66 | M8: {=_xlfn.QUARTILE.INC(TOCOL(J50:N52,1),3)} -> 0.975 | N8: {=MAX(TOCOL(J50:N52,1))} -> 1.45 | P8: CCC | Q8: {=MIN(TOCOL(J63:M66,1))} -> #REF! | R8: {=_xlfn.QUARTILE.INC(TOCOL(J63:M66,1),1)} -> #REF! | S8: {=MEDIAN(TOCOL(J63:M66,1))} -> #REF! | T8: {=_xlfn.QUARTILE.INC(TOCOL(J63:M66,1),3)} -> #REF! | U8: {=MAX(TOCOL(I63:N66,1))} -> #REF! | W8: EBITDA Margin | X8: {=MIN(TOCOL(C77:G77,1))} -> 24.45 | Y8: {=_xlfn.QUARTILE.INC(TOCOL(C77:G77,1),1)} -> 28 | Z8: {=MEDIAN(TOCOL(C77:G77,1))} -> 32.02 | AA8: {=_xlfn.QUARTILE.INC(TOCOL(C77:G77,1),3)} -> 38.21 | AB8: {=MAX(TOCOL(X77:AB80,1))} -> 0.1958 | AD8: Debt to Equity Ratio (DER) | AE8: {=MIN(TOCOL(J49:N49,1))} -> 163 | AF8: {=_xlfn.QUARTILE.INC(TOCOL(J49:N49,1),1)} -> 204 | AG8: {=MEDIAN(TOCOL(J49:N49,1))} -> 245 | AH8: {=_xlfn.QUARTILE.INC(TOCOL(J49:N49,1),3)} -> 302 | AI8: {=MAX(TOCOL(J49:N49,1))} -> 310 | AK8: CCC | AL8: {=MIN(TOCOL(J63:N63,1))} -> 163 | AM8: {=_xlfn.QUARTILE.INC(TOCOL(J63:N63,1),1)} -> 204 | AN8: {=MEDIAN(TOCOL(J63:N63,1))} -> 245 | AO8: {=_xlfn.QUARTILE.INC(TOCOL(J63:N63,1),3)} -> 302 | AP8: {=MAX(TOCOL(J63:N63,1))} -> 310 | AR8: EBITDA Margin | AS8: {=MIN(TOCOL(C78:G78,1))} -> 0.1103 | AT8: {=_xlfn.QUARTILE.INC(TOCOL(C78:G78,1),1)} -> 0.1316 | AU8: {=MEDIAN(TOCOL(C78:G78,1))} -> 0.1417 | AV8: {=_xlfn.QUARTILE.INC(TOCOL(C78:G78,1),3)} -> 0.1426 | AW8: {=MAX(TOCOL(C78:G78,1))} -> 0.146 | AY8: Debt to Equity Ratio (DER) | AZ8: {=MIN(TOCOL(J50:N50,1))} -> 0.41 | BA8: {=_xlfn.QUARTILE.INC(TOCOL(J50:N50,1),1)} -> 0.5 | BB8: {=MEDIAN(TOCOL(J50:N50,1))} -> 0.57 | BC8: {=_xlfn.QUARTILE.INC(TOCOL(J50:N50,1),3)} -> 0.62 | BD8: {=MAX(TOCOL(J50:N50,1))} -> 0.74 | BF8: CCC | BG8: {=MIN(TOCOL(J64:N64,1))} -> #REF! | BH8: {=_xlfn.QUARTILE.INC(TOCOL(J64:N64,1),1)} -> #REF! | BI8: {=MEDIAN(TOCOL(J64:N64,1))} -> #REF! | BJ8: {=_xlfn.QUARTILE.INC(TOCOL(J64:N64,1),3)} -> #REF! | BK8: {=MAX(TOCOL(J64:N64,1))} -> #REF! | BM8: EBITDA Margin | BN8: {=MIN(TOCOL(C79:G79,1))} -> 0.0404 | BO8: {=_xlfn.QUARTILE.INC(TOCOL(C79:G79,1),1)} -> 0.0783 | BP8: {=MEDIAN(TOCOL(C79:G79,1))} -> 0.0893 | BQ8: {=_xlfn.QUARTILE.INC(TOCOL(C79:G79,1),3)} -> 0.0896 | BR8: {=MAX(TOCOL(C79:G79,1))} -> 0.1043 | BT8: Debt to Equity Ratio (DER) | BU8: {=MIN(TOCOL(J51:N51,1))} -> 0.8 | BV8: {=_xlfn.QUARTILE.INC(TOCOL(J51:N51,1),1)} -> 1.03 | BW8: {=MEDIAN(TOCOL(J51:N51,1))} -> 1.14 | BX8: {=_xlfn.QUARTILE.INC(TOCOL(J51:N51,1),3)} -> 1.28 | BY8: {=MAX(TOCOL(J51:N51,1))} -> 1.45 | CA8: CCC | CB8: {=MIN(TOCOL(J65:N65,1))} -> #REF! | CC8: {=_xlfn.QUARTILE.INC(TOCOL(J65:N65,1),1)} -> #REF! | CD8: {=MEDIAN(TOCOL(J65:N65,1))} -> #REF! | CE8: {=_xlfn.QUARTILE.INC(TOCOL(J65:N65,1),3)} -> #REF! | CF8: {=MAX(TOCOL(J65:N65,1))} -> #REF! | CH8: EBITDA Margin | CI8: {=MIN(TOCOL(C80:G80,1))} -> -0.5108 | CJ8: {=_xlfn.QUARTILE.INC(TOCOL(C80:G80,1),1)} -> -0.1457 | CK8: {=MEDIAN(TOCOL(C80:G80,1))} -> 0.0678 | CL8: {=_xlfn.QUARTILE.INC(TOCOL(C80:G80,1),3)} -> 0.0845 | CM8: {=MAX(TOCOL(C80:G80,1))} -> 0.0944 | CO8: Debt to Equity Ratio (DER) | CP8: {=MIN(TOCOL(J52:N52,1))} -> 0.12 | CQ8: {=_xlfn.QUARTILE.INC(TOCOL(J52:N52,1),1)} -> 0.31 | CR8: {=MEDIAN(TOCOL(J52:N52,1))} -> 0.5 | CS8: {=_xlfn.QUARTILE.INC(TOCOL(J52:N52,1),3)} -> 0.66 | CT8: {=MAX(TOCOL(J52:N52,1))} -> 0.92 | CV8: CCC | CW8: {=MIN(TOCOL(J66:N66,1))} -> #REF! | CX8: {=_xlfn.QUARTILE.INC(TOCOL(J66:N66,1),1)} -> #REF! | CY8: {=MEDIAN(TOCOL(J66:N66,1))} -> #REF! | CZ8: {=_xlfn.QUARTILE.INC(TOCOL(J66:N66,1),3)} -> #REF! | DA8: {=MAX(TOCOL(J66:N66,1))} -> #REF!
B9: ROA | C9: {=MIN(TOCOL(R15:V17,1))} -> -0.0592 | D9: {=_xlfn.QUARTILE.INC(TOCOL(R15:V17,1),1)} -> 0.0215 | E9: {=MEDIAN(TOCOL(R15:V17,1))} -> 0.0481 | F9: {=_xlfn.QUARTILE.INC(TOCOL(R15:V17,1),3)} -> 0.09105 | G9: {=MAX(TOCOL(R14:V17,1))} -> 0.1335 | P9: NWC | Q9: {=MIN(TOCOL(C70:F73,1))} -> #REF! | R9: {=_xlfn.QUARTILE.INC(TOCOL(C70:F73,1),1)} -> #REF! | S9: {=MEDIAN(TOCOL(C70:F73,1))} -> #REF! | T9: {=_xlfn.QUARTILE.INC(TOCOL(C70:F73,1),3)} -> #REF! | U9: {=MAX(TOCOL(C70:F73,1))} -> #REF! | W9: ROA | X9: {=MIN(TOCOL(R14:V14,1))} -> 0 | Y9: {=_xlfn.QUARTILE.INC(TOCOL(R14:V14,1),1)} -> #NUM! | Z9: {=MEDIAN(TOCOL(R14:V14,1))} -> #NUM! | AA9: {=_xlfn.QUARTILE.INC(TOCOL(R14:V14,1),3)} -> #NUM! | AB9: {=MAX(TOCOL(R14:V14,1))} -> 0 | AK9: NWC | AL9: {=MIN(TOCOL(C70:G70,1))} -> #REF! | AM9: {=_xlfn.QUARTILE.INC(TOCOL(C70:G70,1),1)} -> #REF! | AN9: {=MEDIAN(TOCOL(C70:G70,1))} -> #REF! | AO9: {=_xlfn.QUARTILE.INC(TOCOL(C70:G70,1),3)} -> #REF! | AP9: {=MAX(TOCOL(C70:G70,1))} -> #REF! | AR9: ROA | AS9: {=MIN(TOCOL(R15:V15,1))} -> 0.0852 | AT9: {=_xlfn.QUARTILE.INC(TOCOL(R15:V15,1),1)} -> 0.0969 | AU9: {=MEDIAN(TOCOL(R15:V15,1))} -> 0.128 | AV9: {=_xlfn.QUARTILE.INC(TOCOL(R15:V15,1),3)} -> 0.1323 | AW9: {=MAX(TOCOL(R15:V15,1))} -> 0.1335 | BF9: NWC | BG9: {=MIN(TOCOL(C71:G71,1))} -> #REF! | BH9: {=_xlfn.QUARTILE.INC(TOCOL(C71:G71,1),1)} -> #REF! | BI9: {=MEDIAN(TOCOL(C71:G71,1))} -> #REF! | BJ9: {=_xlfn.QUARTILE.INC(TOCOL(C71:G71,1),3)} -> #REF! | BK9: {=MAX(TOCOL(C71:G71,1))} -> #REF! | BM9: ROA | BN9: {=MIN(TOCOL(R16:V16,1))} -> 0 | BO9: {=_xlfn.QUARTILE.INC(TOCOL(R16:V16,1),1)} -> 0.0283 | BP9: {=MEDIAN(TOCOL(R16:V16,1))} -> 0.0481 | BQ9: {=_xlfn.QUARTILE.INC(TOCOL(R16:V16,1),3)} -> 0.0654 | BR9: {=MAX(TOCOL(R16:V16,1))} -> 0.0722 | CA9: NWC | CB9: {=MIN(TOCOL(C72:F72,1))} -> #REF! | CC9: {=_xlfn.QUARTILE.INC(TOCOL(C72:F72,1),1)} -> #REF! | CD9: {=MEDIAN(TOCOL(C72:F72,1))} -> #REF! | CE9: {=_xlfn.QUARTILE.INC(TOCOL(C72:F72,1),3)} -> #REF! | CF9: {=MAX(TOCOL(C72:F72,1))} -> #REF! | CH9: ROA | CI9: {=MIN(TOCOL(R17:V17,1))} -> -0.0592 | CJ9: {=_xlfn.QUARTILE.INC(TOCOL(R17:V17,1),1)} -> -0.0513 | CK9: {=MEDIAN(TOCOL(R17:V17,1))} -> 0.0195 | CL9: {=_xlfn.QUARTILE.INC(TOCOL(R17:V17,1),3)} -> 0.0235 | CM9: {=MAX(TOCOL(R17:V17,1))} -> 0.0373 | CV9: NWC | CW9: {=MIN(TOCOL(C73:G73,1))} -> #REF! | CX9: {=_xlfn.QUARTILE.INC(TOCOL(C73:G73,1),1)} -> #REF! | CY9: {=MEDIAN(TOCOL(C73:G73,1))} -> #REF! | CZ9: {=_xlfn.QUARTILE.INC(TOCOL(C73:G73,1),3)} -> #REF! | DA9: {=MAX(TOCOL(C73:G73,1))} -> #REF!
B10: ROE | C10: {=MIN(TOCOL(W15:AA17,1))} -> -0.1998 | D10: {=_xlfn.QUARTILE.INC(TOCOL(W15:AA17,1),1)} -> 0.0212 | E10: {=MEDIAN(TOCOL(W15:AA17,1))} -> 0.208 | F10: {=_xlfn.QUARTILE.INC(TOCOL(W15:AA17,1),3)} -> 0.2835 | G10: {=MAX(TOCOL(W14:AA17,1))} -> 0.3527 | W10: ROE | X10: {=MIN(TOCOL(W14:AA14,1))} -> 0 | Y10: {=_xlfn.QUARTILE.INC(TOCOL(W14:AA14,1),1)} -> #NUM! | Z10: {=MEDIAN(TOCOL(W14:AA14,1))} -> #NUM! | AA10: {=_xlfn.QUARTILE.INC(TOCOL(W14:AA14,1),3)} -> #NUM! | AB10: {=MAX(TOCOL(W14:AA14,1))} -> 0 | AR10: ROE | AS10: {=MIN(TOCOL(W14:AA14,1))} -> 0 | AT10: {=_xlfn.QUARTILE.INC(TOCOL(W14:AA14,1),1)} -> #NUM! | AU10: {=MEDIAN(TOCOL(W14:AA14,1))} -> #NUM! | AV10: {=_xlfn.QUARTILE.INC(TOCOL(W14:AA14,1),3)} -> #NUM! | AW10: {=MAX(TOCOL(W14:AA14,1))} -> 0 | BM10: ROE | BN10: {=MIN(TOCOL(W16:AA16,1))} -> 0 | BO10: {=_xlfn.QUARTILE.INC(TOCOL(W16:AA16,1),1)} -> 0.0316 | BP10: {=MEDIAN(TOCOL(W16:AA16,1))} -> 0.2393 | BQ10: {=_xlfn.QUARTILE.INC(TOCOL(W16:AA16,1),3)} -> 0.242 | BR10: {=MAX(TOCOL(W16:AA16,1))} -> 0.3527 | CH10: ROE | CI10: {=MIN(TOCOL(W17:AA17,1))} -> -0.1998 | CJ10: {=_xlfn.QUARTILE.INC(TOCOL(W17:AA17,1),1)} -> 0.0128 | CK10: {=MEDIAN(TOCOL(W17:AA17,1))} -> 0.0183 | CL10: {=_xlfn.QUARTILE.INC(TOCOL(W17:AA17,1),3)} -> 0.0241 | CM10: {=MAX(TOCOL(W17:AA17,1))} -> 0.2972
B12: Profitability Ratio
B13: Competitor Name | C13: GPM 2025 | D13: GPM 2024 | E13: GPM 2023 | F13: GPM 2022 | G13: GPM 2021 | H13: OPM 2025 | I13: OPM 2024 | J13: OPM 2023 | K13: OPM 2022 | L13: OPM 2021 | M13: NPM 2025 | N13: NPM 2024 | O13: NPM 2023 | P13: NPM 2022 | Q13: NPM 2021 | R13: ROA 2025 | S13: ROA 2024 | T13: ROA 2023 | U13: ROA 2022 | V13: ROA 2021 | W13: ROE 2025 | X13: ROE 2024 | Y13: ROE 2023 | Z13: ROE 2022 | AA13: ROE 2021
B14: PT Pupuk Kalimatan Timur
B15: PT Saraswati Anugerah Makmur Tbk | C15: =D118 -> 0.2125 | D15: =E118 -> 0.246 | E15: =F118 -> 0.2452 | F15: =G118 -> 0.2402 | G15: =H118 -> 0.2559 | H15: =D119 -> 0.0998 | I15: =E119 -> 0.1242 | J15: =F119 -> 0.1352 | K15: =G119 -> 0.1394 | L15: =H119 -> 0.1299 | M15: =D120 -> 0.0627 | N15: =E120 -> 0.079 | O15: =F120 -> 0.091 | P15: =G120 -> 0.0906 | Q15: =H120 -> 0.0893 | R15: =AB112 -> 0.0852 | S15: =AC112 -> 0.1335 | T15: =AD112 -> 0.128 | U15: =AE112 -> 0.1323 | V15: =AF112 -> 0.0969 | W15: =AB111 -> 0.1551 | X15: =AC111 -> 0.2698 | Y15: =AD111 -> 0.336 | Z15: =AE111 -> 0.349 | AA15: =AF111 -> 0.208
B16: PT Delta Giri Wacana Tbk | C16: =D256 -> 0.2675 | D16: =E256 -> 0.2766 | E16: =F256 -> 0.2321 | F16: =G256 -> 0.2263 | G16: =H256 -> 0.2511 | H16: =D257 -> 0.0969 | I16: =E257 -> 0.0827 | J16: =F257 -> 0.0344 | K16: =G257 -> 0.0726 | L16: =H257 -> 0.0837 | M16: =D258 -> 0.0528 | N16: =E258 -> 0.053 | O16: =F258 -> 0.005 | P16: =G258 -> 0.0843 | Q16: =H258 -> 0.0586 | R16: =AB246 -> 0.0722 | S16: =AC246 -> 0.0654 | T16: =AD246 -> 0.0283 | U16: =AE246 -> 0.0481 | V16: 0 | W16: =AB245 -> 0.2393 | X16: =AC245 -> 0.242 | Y16: =AD245 -> 0.0316 | Z16: =AE245 -> 0.3527 | AA16: 0
B17: PT Nusa Palapa Gemilang Tbk | C17: =D431 -> 0.2401 | D17: =E431 -> 0.2453 | E17: =F431 -> 0.0318 | F17: =G431 -> -0.0077 | G17: =H431 -> 0.1629 | H17: =D432 -> 0.047 | I17: =E432 -> 0.0658 | J17: =F432 -> -0.5802 | K17: =G432 -> -0.2039 | L17: =H432 -> 0.0607 | M17: =D433 -> 0.0192 | N17: =E433 -> 0.0178 | O17: =F433 -> 1.1501 | P17: =G433 -> -0.2477 | Q17: =H433 -> 0.0122 | R17: =AB424 -> 0.0195 | S17: =AC424 -> 0.0235 | T17: =AD424 -> -0.0592 | U17: =AE424 -> -0.0513 | V17: =AF424 -> 0.0373 | W17: =AB423 -> 0.0183 | X17: =AC423 -> 0.0128 | Y17: =AD423 -> 0.2972 | Z17: =AE423 -> -0.1998 | AA17: =AF423 -> 0.0241
B19: Rasio Keuangan Quartal 2023-2026 (Berdasarkan 3 Perusahaan Pupuk di Indonesia) | I19: Rasio Keuangan Quartal 2023-2026 (Berdasarkan 3 Perusahaan Pupuk di Indonesia) | P19: Rasio Keuangan Quartal 2023-2026 (Berdasarkan 3 Perusahaan Pupuk di Indonesia) | W19: Rasio Keuangan Quartal 2023-2026 (PT Pupuk Kalimatan Timur) | AD19: Rasio Keuangan Quartal 2023-2026 (PT Pupuk Kalimatan Timur) | AK19: Rasio Keuangan Quartal 2023-2026 (PT Pupuk Kalimatan Timur) | AR19: Rasio Keuangan Quartal 2023-2026 (PT Saraswati Anugerah Makmur Tbk) | AY19: Rasio Keuangan Quartal 2023-2026 (PT Saraswati Anugerah Makmur Tbk) | BF19: Rasio Keuangan Quartal 2023-2026 (PT Saraswati Anugerah Makmur Tbk) | BM19: Rasio Keuangan Quartal 2023-2026 (PT Delta Giri Wacana Tbk) | BT19: Rasio Keuangan Quartal 2023-2026 (PT Delta Giri Wacana Tbk) | CA19: Rasio Keuangan Quartal 2023-2026 (PT Delta Giri Wacana Tbk) | CH19: Rasio Keuangan Quartal 2023-2026 (PT Nusa Palapa Gemilang Tbk) | CO19: Rasio Keuangan Quartal 2023-2026 (PT Nusa Palapa Gemilang Tbk) | CV19: Rasio Keuangan Quartal 2023-2026 (PT Nusa Palapa Gemilang Tbk)
B20: Metric | C20: Min | D20: Q1 / Lower Benchmark | E20: Median | F20: Q3 / Upper Benchmark | G20: Max | I20: Metric | J20: Min | K20: Q1 / Lower Benchmark | L20: Median | M20: Q3 / Upper Benchmark | N20: Max | P20: Metric | Q20: Min | R20: Q1 / Lower Benchmark | S20: Median | T20: Q3 / Upper Benchmark | U20: Max | W20: Metric | X20: Min | Y20: Q1 / Lower Benchmark | Z20: Median | AA20: Q3 / Upper Benchmark | AB20: Max | AD20: Metric | AE20: Min | AF20: Q1 / Lower Benchmark | AG20: Median | AH20: Q3 / Upper Benchmark | AI20: Max | AK20: Metric | AL20: Min | AM20: Q1 / Lower Benchmark | AN20: Median | AO20: Q3 / Upper Benchmark | AP20: Max | AR20: Metric | AS20: Min | AT20: Q1 / Lower Benchmark | AU20: Median | AV20: Q3 / Upper Benchmark | AW20: Max | AY20: Metric | AZ20: Min | BA20: Q1 / Lower Benchmark | BB20: Median | BC20: Q3 / Upper Benchmark | BD20: Max | BF20: Metric | BG20: Min | BH20: Q1 / Lower Benchmark | BI20: Median | BJ20: Q3 / Upper Benchmark | BK20: Max | BM20: Metric | BN20: Min | BO20: Q1 / Lower Benchmark | BP20: Median | BQ20: Q3 / Upper Benchmark | BR20: Max | BT20: Metric | BU20: Min | BV20: Q1 / Lower Benchmark | BW20: Median | BX20: Q3 / Upper Benchmark | BY20: Max | CA20: Metric | CB20: Min | CC20: Q1 / Lower Benchmark | CD20: Median | CE20: Q3 / Upper Benchmark | CF20: Max | CH20: Metric | CI20: Min | CJ20: Q1 / Lower Benchmark | CK20: Median | CL20: Q3 / Upper Benchmark | CM20: Max | CO20: Metric | CP20: Min | CQ20: Q1 / Lower Benchmark | CR20: Median | CS20: Q3 / Upper Benchmark | CT20: Max | CV20: Metric | CW20: Min | CX20: Q1 / Lower Benchmark | CY20: Median | CZ20: Q3 / Upper Benchmark | DA20: Max
B21: Gross Profit Margin (GPM) | C21: {=MIN(TOCOL(C31:P33,1))} -> 0.0435 | D21: {=_xlfn.QUARTILE.INC(TOCOL(C31:P33,1),1)} -> 0.2307 | E21: {=MEDIAN(TOCOL(C31:P33,1))} -> 0.2476 | F21: {=_xlfn.QUARTILE.INC(TOCOL(C31:P33,1),3)} -> 0.2789 | G21: {=MAX(TOCOL(C31:P33,1))} -> 4.5584 | I21: Current Ratio | J21: {=MIN(TOCOL(R42:AE44,1))} -> 1.02 | K21: {=_xlfn.QUARTILE.INC(TOCOL(R42:AE44,1),1)} -> 1.23 | L21: {=MEDIAN(TOCOL(R42:AE44,1))} -> 1.77 | M21: {=_xlfn.QUARTILE.INC(TOCOL(R42:AE44,1),3)} -> 2.515 | N21: {=MAX(TOCOL(R42:AE44,1))} -> 6.11 | P21: DIO | Q21: {=MIN(TOCOL(R57:AE60,1))} -> #REF! | R21: {=_xlfn.QUARTILE.INC(TOCOL(R57:AE60,1),1)} -> #REF! | S21: {=MEDIAN(TOCOL(R57:AE60,1))} -> #REF! | T21: {=_xlfn.QUARTILE.INC(TOCOL(R57:AE60,1),3)} -> #REF! | U21: {=MAX(TOCOL(R57:AE60,1))} -> #REF! | W21: Gross Profit Margin (GPM) | AD21: Current Ratio | AK21: DIO | AR21: Gross Profit Margin (GPM) | AS21: {=MIN(TOCOL(C31:P31,1))} -> 0.1825 | AT21: {=_xlfn.QUARTILE.INC(TOCOL(C31:P31,1),1)} -> 0.2211 | AU21: {=MEDIAN(TOCOL(C31:P31,1))} -> 0.2325 | AV21: {=_xlfn.QUARTILE.INC(TOCOL(C31:P31,1),3)} -> 0.2503 | AW21: {=MAX(TOCOL(C31:P31,1))} -> 0.292 | AY21: Current Ratio | AZ21: {=MIN(TOCOL(R42:AE42,1))} -> 1.47 | BA21: {=_xlfn.QUARTILE.INC(TOCOL(R42:AE42,1),1)} -> 1.5875 | BB21: {=MEDIAN(TOCOL(R42:AE42,1))} -> 1.675 | BC21: {=_xlfn.QUARTILE.INC(TOCOL(R42:AE42,1),3)} -> 1.795 | BD21: {=MAX(TOCOL(R42:AE42,1))} -> 2.05 | BF21: DIO | BG21: {=MIN(TOCOL(R57:AE57,1))} -> #REF! | BH21: {=_xlfn.QUARTILE.INC(TOCOL(R57:AE57,1),1)} -> #REF! | BI21: {=MEDIAN(TOCOL(R57:AE57,1))} -> #REF! | BJ21: {=_xlfn.QUARTILE.INC(TOCOL(R57:AE57,1),3)} -> #REF! | BK21: {=MAX(TOCOL(R57:AE57,1))} -> #REF! | BM21: Gross Profit Margin (GPM) | BN21: {=MIN(TOCOL(C32:P32,1))} -> 0.1852 | BO21: {=_xlfn.QUARTILE.INC(TOCOL(C32:P32,1),1)} -> 0.24715 | BP21: {=MEDIAN(TOCOL(C32:P32,1))} -> 0.27505 | BQ21: {=_xlfn.QUARTILE.INC(TOCOL(C32:P32,1),3)} -> 0.2831 | BR21: {=MAX(TOCOL(C32:P32,1))} -> 0.2946 | BT21: Current Ratio | BU21: {=MIN(TOCOL(R43:AE43,1))} -> 1.02 | BV21: {=_xlfn.QUARTILE.INC(TOCOL(R43:AE43,1),1)} -> 1.1025 | BW21: {=MEDIAN(TOCOL(R43:AE43,1))} -> 1.13 | BX21: {=_xlfn.QUARTILE.INC(TOCOL(R43:AE43,1),3)} -> 1.14 | BY21: {=MAX(TOCOL(R43:AE43,1))} -> 1.15 | CA21: DIO | CB21: {=MIN(TOCOL(R58:AE58,1))} -> #REF! | CC21: {=_xlfn.QUARTILE.INC(TOCOL(R58:AE58,1),1)} -> #REF! | CD21: {=MEDIAN(TOCOL(R58:AE58,1))} -> #REF! | CE21: {=_xlfn.QUARTILE.INC(TOCOL(R58:AE58,1),3)} -> #REF! | CF21: {=MAX(TOCOL(R58:AE58,1))} -> #REF! | CH21: Gross Profit Margin (GPM) | CI21: {=MIN(TOCOL(C33:P33,1))} -> 0.0435 | CJ21: {=_xlfn.QUARTILE.INC(TOCOL(C33:P33,1),1)} -> 0.2388 | CK21: {=MEDIAN(TOCOL(C33:P33,1))} -> 0.2476 | CL21: {=_xlfn.QUARTILE.INC(TOCOL(C33:P33,1),3)} -> 0.2583 | CM21: {=MAX(TOCOL(C33:P33,1))} -> 4.5584 | CO21: Current Ratio | CP21: {=MIN(TOCOL(R44:AE44,1))} -> 1.78 | CQ21: {=_xlfn.QUARTILE.INC(TOCOL(R44:AE44,1),1)} -> 2.305 | CR21: {=MEDIAN(TOCOL(R44:AE44,1))} -> 2.98 | CS21: {=_xlfn.QUARTILE.INC(TOCOL(R44:AE44,1),3)} -> 4.7425 | CT21: {=MAX(TOCOL(R44:AE44,1))} -> 6.11 | CV21: DIO | CW21: {=MIN(TOCOL(R59:AE59,1))} -> #REF! | CX21: {=_xlfn.QUARTILE.INC(TOCOL(R59:AE59,1),1)} -> #REF! | CY21: {=MEDIAN(TOCOL(R59:AE59,1))} -> #REF! | CZ21: {=_xlfn.QUARTILE.INC(TOCOL(R59:AE59,1),3)} -> #REF! | DA21: {=MAX(TOCOL(R59:AE59,1))} -> #REF!
B22: Operating Profit Margin (OPM) | C22: {=MIN(TOCOL(Q31:AD33,1))} -> -6.5618 | D22: {=_xlfn.QUARTILE.INC(TOCOL(Q31:AD33,1),1)} -> 0.064475 | E22: {=MEDIAN(TOCOL(Q31:AD33,1))} -> 0.091 | F22: {=_xlfn.QUARTILE.INC(TOCOL(Q31:AD33,1),3)} -> 0.119675 | G22: {=MAX(TOCOL(Q31:AD33,1))} -> 2.5808 | I22: Quick Ratio | J22: {=MIN(TOCOL(AI42:AV44,1))} -> 0.4 | K22: {=_xlfn.QUARTILE.INC(TOCOL(AI42:AV44,1),1)} -> 0.5825 | L22: {=MEDIAN(TOCOL(AI42:AV44,1))} -> 0.815 | M22: {=_xlfn.QUARTILE.INC(TOCOL(AI42:AV44,1),3)} -> 1.3425 | N22: {=MAX(TOCOL(AI42:AV44,1))} -> 3.01 | P22: DSO | Q22: {=MIN(TOCOL(AI57:AV59,1))} -> #REF! | R22: {=_xlfn.QUARTILE.INC(TOCOL(AI57:AV59,1),1)} -> #REF! | S22: {=MEDIAN(TOCOL(AI57:AV59,1))} -> #REF! | T22: {=_xlfn.QUARTILE.INC(TOCOL(AI57:AV59,1),3)} -> #REF! | U22: {=MAX(TOCOL(AI57:AV59,1))} -> #REF! | W22: Operating Profit Margin (OPM) | AD22: Quick Ratio | AK22: DSO | AR22: Operating Profit Margin (OPM) | AS22: {=MIN(TOCOL(Q31:AD31,1))} -> 0.0905 | AT22: {=_xlfn.QUARTILE.INC(TOCOL(Q31:AD31,1),1)} -> 0.09885 | AU22: {=MEDIAN(TOCOL(Q31:AD31,1))} -> 0.11385 | AV22: {=_xlfn.QUARTILE.INC(TOCOL(Q31:AD31,1),3)} -> 0.1335 | AW22: {=MAX(TOCOL(Q31:AD31,1))} -> 0.1491 | AY22: Quick Ratio | AZ22: {=MIN(TOCOL(AI42:AV42,1))} -> 0.72 | BA22: {=_xlfn.QUARTILE.INC(TOCOL(AI42:AV42,1),1)} -> 0.7625 | BB22: {=MEDIAN(TOCOL(AI42:AV42,1))} -> 0.815 | BC22: {=_xlfn.QUARTILE.INC(TOCOL(AI42:AV42,1),3)} -> 0.9175 | BD22: {=MAX(TOCOL(AI42:AV42,1))} -> 1.2 | BF22: DSO | BG22: {=MIN(TOCOL(AI57:AV57,1))} -> #REF! | BH22: {=_xlfn.QUARTILE.INC(TOCOL(AI57:AV57,1),1)} -> #REF! | BI22: {=MEDIAN(TOCOL(AI57:AV57,1))} -> #REF! | BJ22: {=_xlfn.QUARTILE.INC(TOCOL(AI57:AV57,1),3)} -> #REF! | BK22: {=MAX(TOCOL(AI57:AV57,1))} -> #REF! | BM22: Operating Profit Margin (OPM) | BN22: {=MIN(TOCOL(Q32:AD32,1))} -> -0.0168 | BO22: {=_xlfn.QUARTILE.INC(TOCOL(Q32:AD32,1),1)} -> 0.059975 | BP22: {=MEDIAN(TOCOL(Q32:AD32,1))} -> 0.08005 | BQ22: {=_xlfn.QUARTILE.INC(TOCOL(Q32:AD32,1),3)} -> 0.091175 | BR22: {=MAX(TOCOL(Q32:AD32,1))} -> 0.1318 | BT22: Quick Ratio | BU22: {=MIN(TOCOL(AI43:AV43,1))} -> 0.4 | BV22: {=_xlfn.QUARTILE.INC(TOCOL(AI43:AV43,1),1)} -> 0.48 | BW22: {=MEDIAN(TOCOL(AI43:AV43,1))} -> 0.485 | BX22: {=_xlfn.QUARTILE.INC(TOCOL(AI43:AV43,1),3)} -> 0.5175 | BY22: {=MAX(TOCOL(AI43:AV43,1))} -> 0.55 | CA22: DSO | CB22: {=MIN(TOCOL(AI58:AV58,1))} -> #REF! | CC22: {=_xlfn.QUARTILE.INC(TOCOL(AI58:AV58,1),1)} -> #REF! | CD22: {=MEDIAN(TOCOL(AI58:AV58,1))} -> #REF! | CE22: {=_xlfn.QUARTILE.INC(TOCOL(AI58:AV58,1),3)} -> #REF! | CF22: {=MAX(TOCOL(AI58:AV58,1))} -> #REF! | CH22: Operating Profit Margin (OPM) | CI22: {=MIN(TOCOL(Q33:AD33,1))} -> -6.5618 | CJ22: {=_xlfn.QUARTILE.INC(TOCOL(Q33:AD33,1),1)} -> 0.01085 | CK22: {=MEDIAN(TOCOL(Q33:AD33,1))} -> 0.0755 | CL22: {=_xlfn.QUARTILE.INC(TOCOL(Q33:AD33,1),3)} -> 0.09405 | CM22: {=MAX(TOCOL(Q33:AD33,1))} -> 2.5808 | CO22: Quick Ratio | CP22: {=MIN(TOCOL(AI44:AV44,1))} -> 0.68 | CQ22: {=_xlfn.QUARTILE.INC(TOCOL(AI44:AV44,1),1)} -> 1.1575 | CR22: {=MEDIAN(TOCOL(AI44:AV44,1))} -> 1.6 | CS22: {=_xlfn.QUARTILE.INC(TOCOL(AI44:AV44,1),3)} -> 2.655 | CT22: {=MAX(TOCOL(AI44:AV44,1))} -> 3.01 | CV22: DSO | CW22: {=MIN(TOCOL(AI59:AV59,1))} -> #REF! | CX22: {=_xlfn.QUARTILE.INC(TOCOL(AI59:AV59,1),1)} -> #REF! | CY22: {=MEDIAN(TOCOL(AI59:AV59,1))} -> #REF! | CZ22: {=_xlfn.QUARTILE.INC(TOCOL(AI59:AV59,1),3)} -> #REF! | DA22: {=MAX(TOCOL(AI59:AV59,1))} -> #REF!
B23: Net Profit Margin (NPM) | C23: {=MIN(TOCOL(AE31:AR33,1))} -> -0.0871 | D23: {=_xlfn.QUARTILE.INC(TOCOL(AE31:AR33,1),1)} -> 0.024625 | E23: {=MEDIAN(TOCOL(AE31:AR33,1))} -> 0.059 | F23: {=_xlfn.QUARTILE.INC(TOCOL(AE31:AR33,1),3)} -> 0.07785 | G23: {=MAX(TOCOL(AE31:AR33,1))} -> 3.1477 | I23: Inventory Turnover | J23: {=MIN(TOCOL(R50:AE52,1))} -> 0.71 | K23: {=_xlfn.QUARTILE.INC(TOCOL(R50:AE52,1),1)} -> 1.685 | L23: {=MEDIAN(TOCOL(R50:AE52,1))} -> 2.29 | M23: {=_xlfn.QUARTILE.INC(TOCOL(R50:AE52,1),3)} -> 3.1025 | N23: {=MAX(TOCOL(R50:AE52,1))} -> 3.66 | P23: DPO | Q23: {=MIN(TOCOL(R64:AE66,1))} -> #REF! | R23: {=_xlfn.QUARTILE.INC(TOCOL(R64:AE66,1),1)} -> #REF! | S23: {=MEDIAN(TOCOL(R64:AE66,1))} -> #REF! | T23: {=_xlfn.QUARTILE.INC(TOCOL(R64:AE66,1),3)} -> #REF! | U23: {=MAX(TOCOL(R64:AE66,1))} -> #REF! | W23: Net Profit Margin (NPM) | AD23: Inventory Turnover | AK23: DPO | AR23: Net Profit Margin (NPM) | AS23: {=MIN(TOCOL(AE31:AR31,1))} -> 0.0587 | AT23: {=_xlfn.QUARTILE.INC(TOCOL(AE31:AR31,1),1)} -> 0.06145 | AU23: {=MEDIAN(TOCOL(AE31:AR31,1))} -> 0.0723 | AV23: {=_xlfn.QUARTILE.INC(TOCOL(AE31:AR31,1),3)} -> 0.088375 | AW23: {=MAX(TOCOL(AE31:AR31,1))} -> 0.1028 | AY23: Inventory Turnover | AZ23: {=MIN(TOCOL(R50:AE50,1))} -> 1.59 | BA23: {=_xlfn.QUARTILE.INC(TOCOL(R50:AE50,1),1)} -> 2.4925 | BB23: {=MEDIAN(TOCOL(R50:AE50,1))} -> 3.075 | BC23: {=_xlfn.QUARTILE.INC(TOCOL(R50:AE50,1),3)} -> 3.44 | BD23: {=MAX(TOCOL(R50:AE50,1))} -> 3.66 | BF23: DPO | BG23: {=MIN(TOCOL(R64:AE64,1))} -> #REF! | BH23: {=_xlfn.QUARTILE.INC(TOCOL(R64:AE64,1),1)} -> #REF! | BI23: {=MEDIAN(TOCOL(R64:AE64,1))} -> #REF! | BJ23: {=_xlfn.QUARTILE.INC(TOCOL(R64:AE64,1),3)} -> #REF! | BK23: {=MAX(TOCOL(R64:AE64,1))} -> #REF! | BM23: Net Profit Margin (NPM) | BN23: {=MIN(TOCOL(AE32:AR32,1))} -> -0.0287 | BO23: {=_xlfn.QUARTILE.INC(TOCOL(AE32:AR32,1),1)} -> 0.024625 | BP23: {=MEDIAN(TOCOL(AE32:AR32,1))} -> 0.0405 | BQ23: {=_xlfn.QUARTILE.INC(TOCOL(AE32:AR32,1),3)} -> 0.049725 | BR23: {=MAX(TOCOL(AE32:AR32,1))} -> 0.0889 | BT23: Inventory Turnover | BU23: {=MIN(TOCOL(R51:AE51,1))} -> 2.02 | BV23: {=_xlfn.QUARTILE.INC(TOCOL(R51:AE51,1),1)} -> 2.105 | BW23: {=MEDIAN(TOCOL(R51:AE51,1))} -> 2.27 | BX23: {=_xlfn.QUARTILE.INC(TOCOL(R51:AE51,1),3)} -> 2.34 | BY23: {=MAX(TOCOL(R51:AE51,1))} -> 2.99 | CA23: DPO | CB23: {=MIN(TOCOL(R65:AE65,1))} -> #REF! | CC23: {=_xlfn.QUARTILE.INC(TOCOL(R65:AE65,1),1)} -> #REF! | CD23: {=MEDIAN(TOCOL(R65:AE65,1))} -> #REF! | CE23: {=_xlfn.QUARTILE.INC(TOCOL(R65:AE65,1),3)} -> #REF! | CF23: {=MAX(TOCOL(R65:AE65,1))} -> #REF! | CH23: Net Profit Margin (NPM) | CI23: {=MIN(TOCOL(AE33:AR33,1))} -> -0.0871 | CJ23: {=_xlfn.QUARTILE.INC(TOCOL(AE33:AR33,1),1)} -> 0.00965 | CK23: {=MEDIAN(TOCOL(AE33:AR33,1))} -> 0.03275 | CL23: {=_xlfn.QUARTILE.INC(TOCOL(AE33:AR33,1),3)} -> 0.0969 | CM23: {=MAX(TOCOL(AE33:AR33,1))} -> 3.1477 | CO23: Inventory Turnover | CP23: {=MIN(TOCOL(R52:AE52,1))} -> 0.71 | CQ23: {=_xlfn.QUARTILE.INC(TOCOL(R52:AE52,1),1)} -> 1.075 | CR23: {=MEDIAN(TOCOL(R52:AE52,1))} -> 1.67 | CS23: {=_xlfn.QUARTILE.INC(TOCOL(R52:AE52,1),3)} -> 2.095 | CT23: {=MAX(TOCOL(R52:AE52,1))} -> 3.48 | CV23: DPO | CW23: {=MIN(TOCOL(R66:AE66,1))} -> #REF! | CX23: {=_xlfn.QUARTILE.INC(TOCOL(R66:AE66,1),1)} -> #REF! | CY23: {=MEDIAN(TOCOL(R66:AE66,1))} -> #REF! | CZ23: {=_xlfn.QUARTILE.INC(TOCOL(R66:AE66,1),3)} -> #REF! | DA23: {=MAX(TOCOL(R66:AE66,1))} -> #REF!
B24: EBITDA Margin | C24: {=MIN(TOCOL(R78:AE80,1))} -> -0.3214 | D24: {=_xlfn.QUARTILE.INC(TOCOL(R78:AE80,1),1)} -> 0.0844 | E24: {=MEDIAN(TOCOL(R78:AE80,1))} -> 0.1052 | F24: {=_xlfn.QUARTILE.INC(TOCOL(R78:AE80,1),3)} -> 0.1281 | G24: {=MAX(TOCOL(R78:AE80,1))} -> 2.6303 | I24: Debt to Equity Ratio (DER) | J24: {=MIN(TOCOL(AI50:AV52,1))} -> 0.11 | K24: {=_xlfn.QUARTILE.INC(TOCOL(AI50:AV52,1),1)} -> 0.375 | L24: {=MEDIAN(TOCOL(AI50:AV52,1))} -> 0.685 | M24: {=_xlfn.QUARTILE.INC(TOCOL(AI50:AV52,1),3)} -> 1.035 | N24: {=MAX(TOCOL(AI50:AV52,1))} -> 1.45 | P24: CCC | Q24: {=MIN(TOCOL(AI64:AV66,1))} -> #REF! | R24: {=_xlfn.QUARTILE.INC(TOCOL(AI64:AV66,1),1)} -> #REF! | S24: {=MEDIAN(TOCOL(AI64:AV66,1))} -> #REF! | T24: {=_xlfn.QUARTILE.INC(TOCOL(AI64:AV66,1),3)} -> #REF! | U24: {=MAX(TOCOL(AI64:AV66,1))} -> #REF! | W24: EBITDA Margin | AD24: Debt to Equity Ratio (DER) | AK24: CCC | AR24: EBITDA Margin | AS24: {=MIN(TOCOL(R78:AE78,1))} -> 0.103 | AT24: {=_xlfn.QUARTILE.INC(TOCOL(R78:AE78,1),1)} -> 0.1111 | AU24: {=MEDIAN(TOCOL(R78:AE78,1))} -> 0.1213 | AV24: {=_xlfn.QUARTILE.INC(TOCOL(R78:AE78,1),3)} -> 0.138725 | AW24: {=MAX(TOCOL(R78:AE78,1))} -> 0.1616 | AY24: Debt to Equity Ratio (DER) | AZ24: {=MIN(TOCOL(AI50:AV50,1))} -> 0.41 | BA24: {=_xlfn.QUARTILE.INC(TOCOL(AI50:AV50,1),1)} -> 0.5125 | BB24: {=MEDIAN(TOCOL(AI50:AV50,1))} -> 0.625 | BC24: {=_xlfn.QUARTILE.INC(TOCOL(AI50:AV50,1),3)} -> 0.7575 | BD24: {=MAX(TOCOL(AI50:AV50,1))} -> 0.95 | BF24: CCC | BG24: {=MIN(TOCOL(AI64:AV64,1))} -> #REF! | BH24: {=_xlfn.QUARTILE.INC(TOCOL(AI64:AV64,1),1)} -> #REF! | BI24: {=MEDIAN(TOCOL(AI64:AV64,1))} -> #REF! | BJ24: {=_xlfn.QUARTILE.INC(TOCOL(AI64:AV64,1),3)} -> #REF! | BK24: {=MAX(TOCOL(AI64:AV64,1))} -> #REF! | BM24: EBITDA Margin | BN24: {=MIN(TOCOL(C79:G79,1))} -> 0.0404 | BO24: {=_xlfn.QUARTILE.INC(TOCOL(C79:G79,1),1)} -> 0.0783 | BP24: {=MEDIAN(TOCOL(C79:G79,1))} -> 0.0893 | BQ24: {=_xlfn.QUARTILE.INC(TOCOL(C79:G79,1),3)} -> 0.0896 | BR24: {=MAX(TOCOL(C79:G79,1))} -> 0.1043 | BT24: Debt to Equity Ratio (DER) | BU24: {=MIN(TOCOL(AI51:AV51,1))} -> 1.02 | BV24: {=_xlfn.QUARTILE.INC(TOCOL(AI51:AV51,1),1)} -> 1.05 | BW24: {=MEDIAN(TOCOL(AI51:AV51,1))} -> 1.13 | BX24: {=_xlfn.QUARTILE.INC(TOCOL(AI51:AV51,1),3)} -> 1.165 | BY24: {=MAX(TOCOL(AI51:AV51,1))} -> 1.45 | CA24: CCC | CB24: {=MIN(TOCOL(AI65:AV65,1))} -> #REF! | CC24: {=_xlfn.QUARTILE.INC(TOCOL(AI65:AV65,1),1)} -> #REF! | CD24: {=MEDIAN(TOCOL(AI65:AV65,1))} -> #REF! | CE24: {=_xlfn.QUARTILE.INC(TOCOL(AI65:AV65,1),3)} -> #REF! | CF24: {=MAX(TOCOL(AI65:AV65,1))} -> #REF! | CH24: EBITDA Margin | CI24: {=MIN(TOCOL(C80:G80,1))} -> -0.5108 | CJ24: {=_xlfn.QUARTILE.INC(TOCOL(C80:G80,1),1)} -> -0.1457 | CK24: {=MEDIAN(TOCOL(C80:G80,1))} -> 0.0678 | CL24: {=_xlfn.QUARTILE.INC(TOCOL(C80:G80,1),3)} -> 0.0845 | CM24: {=MAX(TOCOL(C80:G80,1))} -> 0.0944 | CO24: Debt to Equity Ratio (DER) | CP24: {=MIN(TOCOL(AI52:AV52,1))} -> 0.11 | CQ24: {=_xlfn.QUARTILE.INC(TOCOL(AI52:AV52,1),1)} -> 0.12 | CR24: {=MEDIAN(TOCOL(AI52:AV52,1))} -> 0.31 | CS24: {=_xlfn.QUARTILE.INC(TOCOL(AI52:AV52,1),3)} -> 0.375 | CT24: {=MAX(TOCOL(AI52:AV52,1))} -> 0.76 | CV24: CCC | CW24: {=MIN(TOCOL(AI66:AV66,1))} -> #REF! | CX24: {=_xlfn.QUARTILE.INC(TOCOL(AI66:AV66,1),1)} -> #REF! | CY24: {=MEDIAN(TOCOL(AI66:AV66,1))} -> #REF! | CZ24: {=_xlfn.QUARTILE.INC(TOCOL(AI66:AV66,1),3)} -> #REF! | DA24: {=MAX(TOCOL(AI66:AV66,1))} -> #REF!
B25: ROA | C25: {=MIN(TOCOL(AS31:BF33,1))} -> -0.369 | D25: {=_xlfn.QUARTILE.INC(TOCOL(AS31:BF33,1),1)} -> 0.0259 | E25: {=MEDIAN(TOCOL(AS31:BF33,1))} -> 0.061 | F25: {=_xlfn.QUARTILE.INC(TOCOL(AS31:BF33,1),3)} -> 0.1069 | G25: {=MAX(TOCOL(AS31:BF33,1))} -> 0.3004 | P25: NWC | Q25: {=MIN(TOCOL(R71:AE73,1))} -> #REF! | R25: {=_xlfn.QUARTILE.INC(TOCOL(R71:AE73,1),1)} -> #REF! | S25: {=MEDIAN(TOCOL(R71:AE73,1))} -> #REF! | T25: {=_xlfn.QUARTILE.INC(TOCOL(R71:AE73,1),3)} -> #REF! | U25: {=MAX(TOCOL(R71:AE73,1))} -> #REF! | W25: ROA | AK25: NWC | AR25: ROA | AS25: {=MIN(TOCOL(AS31:BF31,1))} -> 0.0456 | AT25: {=_xlfn.QUARTILE.INC(TOCOL(AS31:BF31,1),1)} -> 0.084775 | AU25: {=MEDIAN(TOCOL(AS31:BF31,1))} -> 0.10645 | AV25: {=_xlfn.QUARTILE.INC(TOCOL(AS31:BF31,1),3)} -> 0.136475 | AW25: {=MAX(TOCOL(AS31:BF31,1))} -> 0.1706 | BF25: NWC | BG25: {=MIN(TOCOL(R71:AE71,1))} -> #REF! | BH25: {=_xlfn.QUARTILE.INC(TOCOL(R71:AE71,1),1)} -> #REF! | BI25: {=MEDIAN(TOCOL(R71:AE71,1))} -> #REF! | BJ25: {=_xlfn.QUARTILE.INC(TOCOL(R71:AE71,1),3)} -> #REF! | BK25: {=MAX(TOCOL(R71:AE71,1))} -> #REF! | BM25: ROA | BN25: {=MIN(TOCOL(AS32:BF32,1))} -> 0.0407 | BO25: {=_xlfn.QUARTILE.INC(TOCOL(AS32:BF32,1),1)} -> 0.0517 | BP25: {=MEDIAN(TOCOL(AS32:BF32,1))} -> 0.06435 | BQ25: {=_xlfn.QUARTILE.INC(TOCOL(AS32:BF32,1),3)} -> 0.076025 | BR25: {=MAX(TOCOL(AS32:BF32,1))} -> 0.1261 | CA25: NWC | CB25: {=MIN(TOCOL(R72:AE72,1))} -> #REF! | CC25: {=_xlfn.QUARTILE.INC(TOCOL(R72:AE72,1),1)} -> #REF! | CD25: {=MEDIAN(TOCOL(R72:AE72,1))} -> #REF! | CE25: {=_xlfn.QUARTILE.INC(TOCOL(R72:AE72,1),3)} -> #REF! | CF25: {=MAX(TOCOL(R72:AE72,1))} -> #REF! | CH25: ROA | CI25: {=MIN(TOCOL(AS33:BF33,1))} -> -0.369 | CJ25: {=_xlfn.QUARTILE.INC(TOCOL(AS33:BF33,1),1)} -> -0.0004 | CK25: {=MEDIAN(TOCOL(AS33:BF33,1))} -> 0.0208 | CL25: {=_xlfn.QUARTILE.INC(TOCOL(AS33:BF33,1),3)} -> 0.0342 | CM25: {=MAX(TOCOL(AS33:BF33,1))} -> 0.3004 | CV25: NWC | CW25: {=MIN(TOCOL(R73:AE73,1))} -> #REF! | CX25: {=_xlfn.QUARTILE.INC(TOCOL(AI66:AV66,1),1)} -> #REF! | CY25: {=MEDIAN(TOCOL(AI66:AV66,1))} -> #REF! | CZ25: {=_xlfn.QUARTILE.INC(TOCOL(AI66:AV66,1),3)} -> #REF! | DA25: {=MAX(TOCOL(AI66:AV66,1))} -> #REF!
B26: ROE | C26: {=MIN(TOCOL(BG31:BT33,1))} -> -0.5819 | D26: {=_xlfn.QUARTILE.INC(TOCOL(BG31:BT33,1),1)} -> 0.04805 | E26: {=MEDIAN(TOCOL(BG31:BT33,1))} -> 0.1586 | F26: {=_xlfn.QUARTILE.INC(TOCOL(BG31:BT33,1),3)} -> 0.26275 | G26: {=MAX(TOCOL(BG31:BT33,1))} -> 0.6146 | W26: ROE | AR26: ROE | AS26: {=MIN(TOCOL(BG31:BT31,1))} -> 0.0814 | AT26: {=_xlfn.QUARTILE.INC(TOCOL(BG31:BT31,1),1)} -> 0.1707 | AU26: {=MEDIAN(TOCOL(BG31:BT31,1))} -> 0.24215 | AV26: {=_xlfn.QUARTILE.INC(TOCOL(BG31:BT31,1),3)} -> 0.343975 | AW26: {=MAX(TOCOL(BG31:BT31,1))} -> 0.4883 | BM26: ROE | BN26: {=MIN(TOCOL(BG32:BT32,1))} -> 0.0834 | BO26: {=_xlfn.QUARTILE.INC(TOCOL(BG32:BT32,1),1)} -> 0.108475 | BP26: {=MEDIAN(TOCOL(BG32:BT32,1))} -> 0.1463 | BQ26: {=_xlfn.QUARTILE.INC(TOCOL(BG32:BT32,1),3)} -> 0.185825 | BR26: {=MAX(TOCOL(BG32:BT32,1))} -> 0.4486 | CH26: ROE | CI26: {=MIN(TOCOL(BG33:BT33,1))} -> -0.5819 | CJ26: {=_xlfn.QUARTILE.INC(TOCOL(BG33:BT33,1),1)} -> 0.0026 | CK26: {=MEDIAN(TOCOL(BG33:BT33,1))} -> 0.0152 | CL26: {=_xlfn.QUARTILE.INC(TOCOL(BG33:BT33,1),3)} -> 0.052 | CM26: {=MAX(TOCOL(BG33:BT33,1))} -> 0.6146
B28: Profitability Ratio
B29: Competitor Name | C29: GPM Q2 2026 | D29: GPM Q1 2026 | E29: GPM Q4 2025 | F29: GPM Q3 2025 | G29: GPM Q2 2025 | H29: GPM Q1 2025 | I29: GPM Q4 2024 | J29: GPM Q3 2024 | K29: GPM Q2 2024 | L29: GPM Q1 2024 | M29: GPM Q4 2023 | N29: GPM Q3 2023 | O29: GPM Q2 2023 | P29: GPM Q1 2023 | Q29: OPM Q2 2026 | R29: OPM Q1 2026 | S29: OPM Q4 2025 | T29: OPM Q3 2025 | U29: OPM Q2 2025 | V29: OPM Q1 2025 | W29: OPM Q4 2024 | X29: OPM Q3 2024 | Y29: OPM Q2 2024 | Z29: OPM Q1 2024 | AA29: OPM Q4 2023 | AB29: OPM Q3 2023 | AC29: OPM Q2 2023 | AD29: OPM Q1 2023 | AE29: NPM Q2 2026 | AF29: NPM Q1 2026 | AG29: NPM Q4 2025 | AH29: NPM Q3 2025 | AI29: NPM Q2 2025 | AJ29: NPM Q1 2025 | AK29: NPM Q4 2024 | AL29: NPM Q3 2024 | AM29: NPM Q2 2024 | AN29: NPM Q1 2024 | AO29: NPM Q4 2023 | AP29: NPM Q3 2023 | AQ29: NPM Q2 2023 | AR29: NPM Q1 2023 | AS29: ROA Q2 2026 | AT29: ROA Q1 2026 | AU29: ROA Q4 2025 | AV29: ROA Q3 2025 | AW29: ROA Q2 2025 | AX29: ROA Q1 2025 | AY29: ROA Q4 2024 | AZ29: ROA Q3 2024 | BA29: ROA Q2 2024 | BB29: ROA Q1 2024 | BC29: ROA Q4 2023 | BD29: ROA Q3 2023 | BE29: ROA Q2 2023 | BF29: ROA Q1 2023 | BG29: ROE Q2 2026 | BH29: ROE Q1 2026 | BI29: ROE Q4 2025 | BJ29: ROE Q3 2025 | BK29: ROE Q2 2025 | BL29: ROE Q1 2025 | BM29: ROE Q4 2024 | BN29: ROE Q3 2024 | BO29: ROE Q2 2024 | BP29: ROE Q1 2024 | BQ29: ROE Q4 2023 | BR29: ROE Q3 2023 | BS29: ROE Q2 2023 | BT29: ROE Q1 2023
B30: PT Pupuk Kalimatan Timur
B31: PT Saraswati Anugerah Makmur Tbk | C31: =C172 -> 0.2025 | D31: =D172 -> 0.2307 | E31: =E172 -> 0.1825 | F31: =F172 -> 0.2309 | G31: =G172 -> 0.2072 | H31: =H172 -> 0.2355 | I31: =I172 -> 0.2341 | J31: =J172 -> 0.244 | ... P31: =P172 -> 0.2205 | Q31: =C180 -> 0.0966 | R31: =D180 -> 0.1011 | S31: =E180 -> 0.0981 | T31: =F180 -> 0.1117 | U31: =G180 -> 0.094 | V31: =H180 -> 0.0905 | W31: =I180 -> 0.1116 | X31: =J180 -> 0.1209 | ... AD31: =P180 -> 0.1356 | AE31: =C174 -> 0.0593 | AF31: =D174 -> 0.0625 | AG31: =E174 -> 0.0587 | AH31: =F174 -> 0.0697 | AI31: =G174 -> 0.0611 | AJ31: =H174 -> 0.0594 | AK31: =I174 -> 0.0689 | AL31: =J174 -> 0.0749 | ... AR31: =P174 -> 0.0918 | AS31: =AZ165 -> 0.0456 | AT31: =BA165 -> 0.0883 | AU31: =BB165 -> 0.1069 | AV31: =BC165 -> 0.0742 | AW31: =BD165 -> 0.0588 | AX31: =BE165 -> 0.1052 | AY31: =BF165 -> 0.1113 | AZ31: =BG165 -> 0.106 | ... BF31: =BM165 -> 0.143 | BG31: =AZ164 -> 0.0814 | BH31: =BA164 -> 0.1642 | BI31: =BB164 -> 0.2368 | BJ31: =BC164 -> 0.1586 | BK31: =BD164 -> 0.1174 | BL31: =BE164 -> 0.2127 | BM31: =BF164 -> 0.278 | BN31: =BG164 -> 0.2475 | ... BT31: =BM164 -> 0.443
B32: PT Delta Giri Wacana Tbk | C32: =C319 -> 0.2699 | D32: =D319 -> 0.2429 | E32: =E319 -> 0.2404 | F32: =F319 -> 0.2825 | G32: =G319 -> 0.2802 | H32: =H319 -> 0.2808 | I32: =I319 -> 0.2946 | J32: =J319 -> 0.2599 | ... P32: =P319 -> 0.1852 | Q32: =C320 -> 0.0915 | R32: =D320 -> 0.0888 | S32: =E320 -> 0.1264 | T32: =F320 -> 0.1051 | U32: =G320 -> 0.059 | V32: =H320 -> 0.0713 | W32: =I320 -> 0.1318 | X32: =J320 -> 0.0692 | ... AD32: =P320 -> -0.0168 | AE32: =C321 -> 0.0392 | AF32: =D321 -> 0.0447 | AG32: =E321 -> 0.0769 | AH32: =F321 -> 0.0514 | AI32: =G321 -> 0.031 | AJ32: =H321 -> 0.0322 | AK32: =I321 -> 0.0889 | AL32: =J321 -> 0.0663 | ... AR32: =P321 -> -0.0287 | AS32: =AZ323 -> 0.061 | AT32: =BA323 -> 0.1261 | AU32: =BB323 -> 0.0788 | AV32: =BC323 -> 0.0407 | AW32: =BD323 -> 0.0486 | AX32: =BE323 -> - | AY32: =BF323 -> - | AZ32: =BG323 -> - | ... BF32: =BM323 | BG32: =AZ322 -> 0.1783 | BH32: =BA322 -> 0.4486 | BI32: =BB322 -> 0.2084 | BJ32: =BC322 -> 0.1126 | BK32: =BD322 -> 0.1161 | BL32: =BE322 -> - | BM32: =BF322 -> - | BN32: =BG322 -> 0.0834 | ... BT32: =BM322
B33: PT Nusa Palapa Gemilang Tbk | C33: =C482 -> 0.2067 | D33: =D482 -> 0.2454 | E33: =E482 -> 0.2047 | F33: =F482 -> 0.2746 | G33: =G482 -> 0.256 | H33: =H482 -> 0.2583 | I33: =I482 -> 0.2388 | J33: =J482 -> 0.2541 | ... P33: =P482 -> - | Q33: =C483 -> 0.0526 | R33: =D483 -> 0.0962 | S33: =E483 -> 0.0011 | T33: =F483 -> 0.0734 | U33: =G483 -> 0.0876 | V33: =H483 -> 0.0828 | W33: =I483 -> 0.0401 | X33: =J483 -> 0.0776 | ... AD33: =P483 -> -6.5618 | AE33: =C484 -> 0.0072 | AF33: =D484 -> 0.0188 | AG33: =E484 -> 0.0032 | AH33: =F484 -> 0.0434 | AI33: =G484 -> 0.017 | AJ33: =H484 -> 0.0221 | AK33: =I484 -> -0.0057 | AL33: =J484 -> 0.0473 | ... AR33: =P484 -> 3.1477 | AS33: =AZ478 -> - | AT33: =BA478 -> 0.0008 | AU33: =BB478 -> 0.0342 | AV33: =BC478 -> 0.0208 | AW33: =BD478 -> 0.0259 | AX33: =BE478 -> 0.0231 | AY33: =BF478 -> 0.0354 | AZ33: =BG478 -> 0.0433 | ... BF33: =BM478 -> -0.1951 | BG33: =AZ477 -> - | BH33: =BA477 -> 0.005 | BI33: =BB477 -> 0.0441 | BJ33: =BC477 -> 0.0089 | BK33: =BD477 -> 0.0152 | BL33: =BE477 -> -0.0065 | BM33: =BF477 -> 0.0393 | BN33: =BG477 -> 0.052 | ... BT33: =BM477 -> -0.5819
C36: 2026 Kuartal I GPM | D36: OPM | E36: NPM
B37: 601660833660 | C37: =138844581061/601660833660 -> 0.23076885 | E37: =38810585879/B37 -> 0.064505754
B39: Current Ratio | C39: TAHUNAN | I39: Quick Ratio | J39: TAHUNAN | Q39: Current Ratio | R39: QUARTAL | AH39: Quick Ratio | AI39: QUARTAL
C40: FY 2025 | D40: FY 2024 | E40: FY 2023 | F40: FY 2022 | G40: FY 2021 | J40: FY 2025 | K40: FY 2024 | L40: FY 2023 | M40: FY 2022 | N40: FY 2021 | R40: Q2 2026 | S40: Q1 2026 | T40: Q4 2025 | U40: Q3 2025 | V40: Q2 2025 | W40: Q1 2025 | X40: Q4 2024 | Y40: Q3 2024 | Z40: Q2 2024 | AA40: Q1 2024 | AB40: Q4 2023 | AC40: Q3 2023 | AD40: Q2 2023 | AE40: Q1 2023 | AI40: Q2 2026 | AJ40: Q1 2026 | AK40: Q4 2025 | AL40: Q3 2025 | AM40: Q2 2025 | AN40: Q1 2025 | AO40: Q4 2024 | AP40: Q3 2024 | AQ40: Q2 2024 | AR40: Q1 2024 | AS40: Q4 2023 | AT40: Q3 2023 | AU40: Q2 2023 | AV40: Q1 2023
B41: PT Pupuk Kalimatan Timur | C41: 310 | D41: 302 | E41: 204 | F41: 245 | G41: 163 | I41: PT Pupuk Kalimatan Timur | J41: 310 | K41: 302 | L41: 204 | M41: 245 | N41: 163 | Q41: PT Pupuk Kalimatan Timur | AH41: PT Pupuk Kalimatan Timur
B42: PT Saraswati Anugerah Makmur Tbk | C42: =AB110 -> 1.98 | D42: =AC110 -> 2.05 | E42: =AD110 -> 1.76 | F42: =AE110 -> 1.39 | G42: =AF110 -> 1.6 | I42: PT Saraswati Anugerah Makmur Tbk | J42: =AB109 -> 1.2 | K42: =AC109 -> 1.19 | L42: =AD109 -> 0.72 | M42: =AE109 -> 0.47 | N42: =AF109 -> 0.68 | Q42: PT Saraswati Anugerah Makmur Tbk | R42: =AZ163 -> 1.47 | S42: =BA163 -> 1.8 | T42: =BB163 -> 1.98 | U42: =BC163 -> 1.7 | V42: =BD163 -> 1.64 | W42: =BE163 -> 1.97 | X42: =BF163 -> 2.05 | Y42: =BG163 -> 1.65 | ... AE42: =BM163 -> 1.55 | AH42: PT Saraswati Anugerah Makmur Tbk | AI42: =AZ162 -> 0.72 | AJ42: =BA162 -> 0.77 | AK42: =BB162 -> 1.2 | AL42: =BC162 -> 0.91 | AM42: =BD162 -> 0.75 | AN42: =BE162 -> 0.89 | AO42: =BF162 -> 1.19 | AP42: =BG162 -> 0.92 | ... AV42: =BM162 -> 0.76
B43: PT Delta Giri Wacana Tbk | C43: =AB244 -> 1.14 | D43: =AC244 -> 1.02 | E43: =AD244 -> 1.15 | F43: =AE244 -> 1.22 | G43: =AF244 -> 1.27 | I43: PT Delta Giri Wacana Tbk | J43: =AB243 -> 0.51 | K43: =AC243 -> 0.52 | L43: =AD243 -> 0.48 | M43: =AE243 -> 0.59 | N43: =AF243 -> 0.85 | Q43: PT Delta Giri Wacana Tbk | R43: =AZ321 -> 1.12 | S43: =BA321 -> 1.14 | T43: =BB321 -> 1.14 | U43: =BC321 -> 1.11 | V43: =BD321 -> 1.1 | W43: =BE321 -> 1.14 | X43: =BF321 -> 1.02 | Y43: =BG321 -> - | ... AE43: =BM321 -> - | AH43: PT Delta Giri Wacana Tbk | AI43: =AZ320 -> 0.4 | AJ43: =BA320 -> 0.48 | AK43: =BB320 -> 0.51 | AL43: =BC320 -> 0.45 | AM43: =BD320 -> 0.54 | AN43: =BE320 -> 0.55 | AO43: =BF320 -> 0.52 | AP43: =BG320 -> - | ... AV43: =BM320 -> -
B44: PT Nusa Palapa Gemilang Tbk | C44: =AB422 -> 2.2 | D44: =AC422 -> 2.99 | E44: =AD422 -> 5.18 | F44: =AE422 -> 0.83 | G44: =AF422 -> 1.26 | I44: PT Nusa Palapa Gemilang Tbk | J44: =AB421 -> 1.39 | K44: =AC421 -> 1.68 | L44: =AD421 -> 2.58 | M44: =AE421 -> 0.55 | N44: =AF421 -> 0.83 | Q44: PT Nusa Palapa Gemilang Tbk | R44: =AZ476 -> 1.78 | S44: =BA476 -> 1.79 | T44: =BB476 -> 2.2 | U44: =BC476 -> 2.67 | V44: =BD476 -> 2.97 | W44: =BE476 -> 2.62 | X44: =BF476 -> 2.99 | Y44: =BG476 -> 5.9 | ... AE44: =BM476 -> 3.43 | AH44: PT Nusa Palapa Gemilang Tbk | AI44: =AZ475 -> 1.07 | AJ44: =BA475 -> 1.08 | AK44: =BB475 -> 1.39 | AL44: =BC475 -> 1.54 | AM44: =BD475 -> 1.6 | AN44: =BE475 -> 1.6 | AO44: =BF475 -> 1.68 | AP44: =BG475 -> 2.68 | ... AW44: =BN475
B47: Inventory Turnover | C47: TAHUNAN | I47: Debt to Equity Ratio (DER) | J47: TAHUNAN | Q47: Inventory Turnover | R47: QUARTAL | AH47: Debt to Equity Ratio (DER) | AI47: QUARTAL
C48: FY 2025 | D48: FY 2024 | E48: FY 2023 | F48: FY 2022 | G48: FY 2021 | J48: FY 2025 | K48: FY 2024 | L48: FY 2023 | M48: FY 2022 | N48: FY 2021 | R48: Q2 2026 | S48: Q1 2026 | T48: Q4 2025 | U48: Q3 2025 | V48: Q2 2025 | W48: Q1 2025 | X48: Q4 2024 | Y48: Q3 2024 | Z48: Q2 2024 | AA48: Q1 2024 | AB48: Q4 2023 | AC48: Q3 2023 | AD48: Q2 2023 | AE48: Q1 2023 | AI48: Q2 2026 | AJ48: Q1 2026 | AK48: Q4 2025 | AL48: Q3 2025 | AM48: Q2 2025 | AN48: Q1 2025 | AO48: Q4 2024 | AP48: Q3 2024 | AQ48: Q2 2024 | AR48: Q1 2024 | AS48: Q4 2023 | AT48: Q3 2023 | AU48: Q2 2023 | AV48: Q1 2023
B49: PT Pupuk Kalimatan Timur | C49: 310 | D49: 302 | E49: 204 | F49: 245 | G49: 163 | I49: PT Pupuk Kalimatan Timur | J49: 310 | K49: 302 | L49: 204 | M49: 245 | N49: 163 | Q49: PT Pupuk Kalimatan Timur | AH49: PT Pupuk Kalimatan Timur
...
