Workbook

Sheet LK Summary Data
A1: SUMMARY LABA RUGI 2026
A2: KONSOL & STAND ALONE
A5: Monthly Laba Rugi Konsolidasi 2026 | AB5: Monthly Neraca Konsolidasi 2026 | CF5: Monthly Arus Kas Konsolidasi 2026 | DQ5: Monthly CALK Konsolidasi 2026
B6: Penjualan | C6: Harga Pokok Penjualan | D6: Laba Kotor | E6: Beban Usaha | F6: Beban Umum dan Administrasi | G6: Beban Penjualan dan Pemasaran | H6: Beban Analisa Lab | I6: Jumlah Beban Usaha | J6: Laba Usaha | K6: Pendapatan (Beban) Lain-lain | L6: Pendapatan Lain-lain | M6: Beban Diluar Usaha Lainnya | N6: Jumlah Pendapatan (Beban) Lain-lain | P6: Laba Sebelum Pajak | Q6: Beban Pajak Penghasilan | R6: Pajak tangguhan | S6: Jumlah Beban Pajak | T6: Laba Bersih Setelah Pajak | U6: Penghasilan Komprehensif Lain | V6: Keuntungan/Kerugian aktuarial | W6: atas liabilitas imbalan kerja | X6: Jumlah Penghasilan (Rugi) Komprehensif Lain | AB6: ASET | AC6: Aset Lancar | AD6: Kas dan Setara Kas | AE6: Piutang Usaha | AF6: Anjak Piutang | AG6: Cadangan Kerugian Piutang Tak Tertagih | AH6: Piutang Lain Pihak Terkait | AI6: Persediaan | AJ6: Persediaan dalam Proses | AK6: Persediaan Barang Dagang | AL6: Biaya Dibayar Dimuka | AM6: Pajak Dibayar Dimuka | AN6: Jumlah Aset Lancar | AO6: Aset Tidak Lancar | AP6: Investasi | AQ6: Aset Tetap | AR6: Aset Tidak Lancar Lainnya | AU6: Aset Pajak Tangguhan | AV6: Jumlah Aset Tidak Lancar | AW6: Jumlah Aset | AY6: LIABILITAS DAN EKUITAS | AZ6: Liabilitas Lancar | BA6: Hutang Usaha | BC6: Barang yang belum terinvoice | BD6: Persediaan Barang Diterima Belum di BAST (LPB) | BE6: Hutang Pajak | BF6: Uang Muka Penjualan | BI6: Hutang Lain-Lain | BJ6: Hutang Bunga Bank | BK6: Hutang Bank Jangka Pendek | BL6: Jumlah Liabilitas Lancar | BM6: Liabilitas Tidak Lancar | BN6: Hutang Bank Jangka Panjang | BO6: Hutang Leasing | BP6: Hutang Pemegang Saham | BQ6: Hutang Imbalan Pasca Kerja | BR6: Liabilitas pajak tangguhan | BS6: Jumlah Liabilitas Tidak Lancar | BT6: Jumlah Liabilitas | BU6: Ekuitas | BV6: Modal Disetor | BW6: Saldo Laba | BX6: Laba-Rugi Periode Berjalan | BY6: Laba-Rugi Ditahan | BZ6: Akumulasi penghasilan komprehensif lain | CA6: Kepentingan non pengendali - Rugi/Laba | CB6: Kepentingan non pengendali - Modal | CC6: Jumlah Ekuitas | CD6: Jumlah Liabilitas dan Ekuitas | CG6: Arus Kas dari Aktivitas Operasi | CH6: Laba (rugi) bersih | CI6: Penyesuaian : | CJ6: Penyusutan | CK6: Akumulasi Komprehensif Lain | CM6: Penurunan (Kenaikan) : | CN6: Piutang usaha | CO6: Anjak Piutang | CP6: Piutang Afiliasi & Lainnya | CQ6: Biaya dibayar dimuka | CR6: Pajak dibayar dimuka | CS6: Persediaan | CT6: Kenaikan (Penurunan) : | CU6: Utang Usaha | CV6: Hutang Afiliasi & Lainnya | CW6: Utang Pajak | CX6: Uang Muka Penjualan | CY6: Biaya yg masih harus dibayar | CZ6: Hutang jangka Panjang | DA6: Kas Bersih yang digunakan untuk Aktivitas Operasi | DB6: Arus Kas dari Aktivitas Investasi : | DC6: (Penambahan) Pengurangan Aset Tetap | DD6: (Penambahan) Pengurangan Investasi | DE6: (Penambahan) Pengurangan Konstruksi Dalam Pengerjaan | DF6: Kas Bersih yang diperoleh/ digunakan untuk Aktivitas Investasi | DG6: Arus Kas dari Aktivitas Pendanaan : | DH6: Utang Bank | DI6: Modal di setor | DJ6: Kas Bersih yang diperoleh/ digunakan untuk Aktivitas Pendanaan | DK6: Kenaikan Kas & Setara Kas | DL6: Kas & Setara Kas awal periode | DM6: Kas & Setara Kas akhir periode | DR6: Penjualan | DT6: Retur Penjualan | DU6: Diskon Penjualan | DV6: Jumlah Penjualan | DX6: BEBAN POKOK PENJUALAN | DY6: Harga Pokok Penjualan Afiliasi | DZ6: Harga Pokok Penjualan Non Afiliasi | EA6: Beban Bea Masuk Import | EE6: Beban Penyusutan Mesin | EF6: Beban Pemeliharaan Mesin Ew | EG6: Beban Pemeliharaan Mesin Line 1 | EH6: Beban Pemeliharaan Mesin Line 2 | EI6: Beban Pemeliharaan Mesin Line 3 | EJ6: Beban Pemeliharaan Mesin Line 4 | EK6: Beban Pemeliharaan Mesin Line 5 | EL6: Beban Pemeliharaan Mesin Copper Sulphate | EM6: Beban Penyusutan Peralatan Pabrik | EO6: Beban Sewa Kendaraan | EP6: Selisih Stock Opname | EQ6: Selisih Timbang | ER6: Beban Tenaga Kerja Langsung | ES6: Beban Transportasi Bahan Baku | ET6: Beban Transportasi Produk Jadi | EU6: Beban Transportasi Produk Jadi (Bonus dan Fee Marketing) | EV6: Beban Pemeliharaan Kendaraan Pabrik | EW6: Beban Pemeliharaan Aset Pabrik | EX6: Beban Rumah Tangga Pabrik | EY6: Beban Gaji Staff Pabrik | EZ6: Beban Tenaga Kerja Tidak Langsung | FA6: Beban Pemeliharaan Mesin Pramaterial | FC6: Beban Listrik Pabrik | FD6: Beban Listrik Pabrik (Gudang Timur) | FF6: Beban Transportasi Lainnya | FG6: Beban Perlengkapan Pabrik | FI6: Beban Bbm Pabrik | FJ6: Beban Bongkar | FK6: Beban Qc Produk | FL6: Beban Transportasi Impor | FM6: Beban Gudang Pelabuhan | FN6: Beban Administrasi Pabean | FO6: Beban Muat | FQ6: Beban Klaim | FR6: Beban Gaji PHL | FV6: Beban Asuransi Pengiriman | FW6: Beban Sample | FX6: Beban Demplot | FZ6: Beban Pemeliharaan Bangunan Pabrik | GA6: Beban Pemeliharaan Sarana Prasarana Pabrik | GB6: Beban Perlengkapan Mekanik | GC6: Beban Perlengkapan Elektrikal | GD6: Beban Pemeliharaan Mesin Crf | GE6: Beban Riset Dan Percobaan Lapangan | GF6: Beban Pemeliharaan Mesin Copper Sulphate Line 2 | GG6: Beban Pemeliharaan Aset Lab | GH6: Beban Operasional Gudang | GI6: Beban Uji Dosis (Internal) | GJ6: Beban Perlengkapan Lab | GK6: Beban Kerugian Bibit Afkir | GL6: Beban Pemeliharaan Mesin NPK | GM6: Jumlah Harga Pokok Penjualan | GO6: BEBAN UMUM DAN ADMINISTRASI | GQ6: Beban Pelatihan | GR6: Beban Pelatihan Internal | GS6: Beban Perlengkapan Kantor | GT6: Beban Hse | GU6: Beban Penyusutan Kendaraan | GV6: Beban Penyusutan Inventaris Kantor | GW6: Beban Amortisasi Ditangguhkan SHGB | GX6: Beban Penyusutan Bangunan | GY6: Beban Gaji BOD | GZ6: Beban Gaji Staff Kantor | HC6: Tunjangan Lembur | HF6: Tunjangan Hari Raya - THR | HG6: Beban Asuransi - BPJS KES | HH6: Beban Asuransi - BPJS TK | HI6: Beban Pemeliharaan Aset Kantor | HJ6: Beban Rumah Tangga Kantor | HK6: Beban Pengembangan System/Software | HL6: Beban Kompensasi Ganti Rugi | HM6: Beban Koreksi Fiskal | HN6: Beban Asuransi Kebakaran | HO6: Beban Pemeliharaan Kendaraan Kantor | HP6: Beban Bbm Kantor | HQ6: Beban Perjalanan Dinas Kantor | HR6: Beban Perjalanan Dinas Tamu | HS6: Beban Obat/Pengobatan | HT6: Beban Sewa | HU6: Biaya Legal Dan Perijinan | HV6: Beban Rakor | HW6: Beban Audit | HX6: Beban Perayaan Hari Besar | HY6: Beban Atk Kantor | HZ6: Beban Internet/Vsat | IA6: Beban Cetak/Fotocopy | IB6: Beban Air Minum Kantor | IC6: Beban Konsumsi Dan Oleh-Oleh Tamu | ID6: Beban Kirim Paket (Sampel/Dokumen) | IE6: Beban Listrik Kantor | IF6: Beban Telepon Kantor | IG6: Pajak Kendaraan & PBB | IH6: Beban Suka/Duka | IK6: Beban Pph 4 Ayat 2 | IL6: Beban Pph Pasal 23 | IM6: Beban Pph Pasal 21 | IN6: Beban Pph 25 | IO6: Beban Pinalti Pajak | IP6: Beban Pph Pasal 29 | IQ6: Beban Olahraga Dan Rekreasi | IR6: Biaya Kaizen | IS6: Beban Pemutusan Hubungan Kerja | IT6: Beban Apraisal | IU6: Beban Konsultan Keuangan | IV6: Beban Bphtb | IW6: Beban Kerugian Investasi | IX6: Beban Apresiasi Karyawan | IY6: Beban Imbalan Pasca Kerja | IZ6: Beban Notaris | JA6: Beban Gaji Staff Laboratorium | JB6: Beban Csr (Corporate Social Responsibility) | JC6: Beban Cadangan Kerugian Piutang Tak Tertagih | JD6: Beban Brand Development | JE6: Beban Ppn Tidak Bisa Dikreditkan | JH6: Beban Penyusutan Software | JI6: Beban Rekrutmen | JJ6: Beban Rups | JK6: Beban Aktuaria | JL6: Beban Riset Corporate & Strategy | JM6: Beban Gaji Managemen | JN6: Beban Gaji Principal | JO6: Beban Sarana Prasarana Kantor | JP6: Beban Outsourcing | JQ6: Biaya Pemeliharaan Bangunan Kantor | JR6: Beban Beasiswa | JS6: Beban Kesejahteraan Karyawan | JT6: Jumlah Beban Administrasi dan Umum | JV6: BEBAN PENJUALAN DAN PEMASARAN | JW6: Beban Operasional Pemasaran | JX6: Beban Relasi | JY6: Beban Promosi | JZ6: Jumlah Beban Penjualan dan Pemasaran | KB6: BEBAN ANALISA LAB | KC6: Beban Analisa Lab | KD6: Jumlah Analisa Lab | KF6: PENDAPATAN | KG6: Pendapatan Jasa Giro | KH6: Pendapatan Lain-Lain | KI6: Pendapatan Selisih Lebih Kurs | KJ6: Pendapatan Aval | KK6: Pendapatan Selisih Koma | KL6: Pendapatan Klaim | KM6: Pendapatan Jasa Maklon | KN6: Jumlah Pendapatan | KP6: BEBAN DILUAR USAHA | KQ6: Beban Adm Bank | KR6: Beban Marjin Pinjaman | KT6: Beban Administrasi Kredit - Mk | KV6: Beban Selisih Kurang Kurs | KW6: Beban Selisih Koma | KX6: Beban Market Place | KY6: Beban Lain-Lain | KZ6: Beban Zakat | LB6: Beban Qurban | LC6: Beban Administrasi Kredit - LC/SKBDN | LE6: Jumlah Beban Diluar Usaha | LG6: PAJAK PENGHASILAN | LH6: Beban Pajak Penghasilan | LI6: Jumlah Pajak Penghasilan | LJ6: Jumlah Beban | LK6: EBITDA
A7: January | B7: 22271442059 | C7: 14550282537 | D7: 7721159523 | F7: 2811522986 | G7: 689993629 | H7: 85297200 | I7: 3586813815 | J7: 4134345708 | L7: 14972802 | M7: 1999371672 | N7: -1984398870 | P7: 2149946838 | Q7: 686000 | S7: 686000 | T7: 2149260838 | W7: 0 | X7: 2149260838 | AD7: 44214340653 | AE7: 44331095704 | AG7: -325897486 | AH7: 10333743154 | AI7: 104300563162 | AJ7: - | AL7: 27470911203 | AM7: 12165949131 | AN7: 242490705521 | AP7: - | AQ7: 127315422381 | AR7: 6707849388 | AU7: 1712002768 | AV7: 135735274537 | AW7: 378225980058 | BA7: 21736710978 | BC7: - | BD7: - | BE7: 5705977764 | BF7: 9760447198 | BI7: 145767226 | BJ7: - | BK7: 198250150994 | BL7: 235599054161 | BN7: 10372247233 | BO7: - | BQ7: 5424840824 | BR7: - | BS7: 15797088057 | BT7: 251396142218 | BV7: 68245000000 | BW7: - | BX7: 2162513125 | BY7: 53985061075 | BZ7: -541805960 | CA7: - | CB7: 2979069600 | CC7: 126829837839 | CD7: 378225980058 | CF7: January | DQ7: January | DR7: 22321496113 | DT7: -49804054 | DU7: -250000 | DV7: 22271442059 | DZ7: 11233807019 | EA7: 419236000 | EE7: 222361613 | EF7: 175478 | EG7: 3802702 | EH7: 3154533 | EI7: 19358144 | EJ7: 328037 | EK7: 3330313 | EL7: 99249577 | EM7: 36077806 | EO7: 60150000 | EP7: 9103283 | ER7: 326841928 | ES7: 59495840 | ET7: 1256104694 | EV7: 527050 | EY7: 73522457 | EZ7: 161256537 | FA7: 10059662 | FC7: 78314507 | FD7: 22316357 | FF7: 5981156 | FG7: 214800 | FI7: 12000000 | FJ7: 22472770 | FO7: 13196810 | FR7: 117593000 | FV7: 53400200 | FW7: 23953018 | FZ7: 83382614 | GA7: 56657612 | GB7: 14957210 | GC7: 7356377 | GD7: 315543 | GE7: 15133876 | GF7: 437015 | GG7: 24510000 | GH7: 147000 | GM7: 14550282537 | GQ7: 33272500 | GR7: 59048061 | GS7: 155000 | GT7: 23945243 | GU7: 82255996 | GV7: 47123961 | GW7: 22118501 | GX7: 229723827 | GY7: 403465056 | GZ7: 453491678 | HC7: 40204681 | HG7: 29664522 | HH7: 61503254 | HI7: 225000 | HJ7: 48106641 | HK7: 712553 | HN7: 2502709 | HO7: 28181917 | HP7: 5290000 | HQ7: 116650988 | HR7: 8832900 | HT7: 54003207 | HU7: 59550000 | HV7: 49160000 | HX7: 124627563 | HY7: 1996000 | HZ7: 7520728 | IA7: 2529592 | IB7: 3316499 | IC7: 20354381 | ID7: 16661730 | IE7: 17158107 | IF7: 3178477 | IG7: 18466200 | IM7: 77824374 | IQ7: 380000 | JB7: 80200000 | JH7: 7339144 | JM7: 420042284 | JN7: 46928088 | JO7: 765000 | JP7: 41576967 | JQ7: 28962413 | JS7: 16440000 | JT7: 2797455742 | JW7: 491945849 | JX7: 147499000 | JY7: 50548780 | JZ7: 689993629 | KC7: 85297200 | KD7: 85297200 | KG7: 9971413 | KK7: 1389 | KN7: 14972802 | KQ7: 10483936 | KR7: 1612378407 | KT7: 103409480 | KV7: 217846340 | KW7: 2175 | LC7: 5933631 | LE7: 2000053970 | LH7: 818660 | LI7: 818660 | LJ7: =LE7+KD7+JZ7+JT7 -> 5572800541
A8: February | B8: 39926611384 | C8: 27445523058 | D8: 12481088327 | F8: 3136682077 | G8: 944187719 | H8: 5467002 | I8: 4086336797 | J8: 8394751529 | L8: 346889484 | M8: 2924246807 | N8: -2577357324 | P8: 5817394206 | Q8: 120515 | S8: 120515 | T8: 5817273691 | W8: 0 | X8: 5817273691 | AD8: 20099667310 | AE8: 49863908492 | AG8: -325897486 | AH8: 10184417154 | AI8: 119522871582 | AJ8: - | AL8: 9744087704 | AM8: 16589488907 | AN8: 225678543663 | AP8: - | AQ8: 130348634297 | AR8: 6678391743 | AU8: 1712002768 | AV8: 138739028808 | AW8: 364417572471 | BA8: 15356991892 | BC8: - | BD8: - | BE8: 8435842992 | BF8: 8132536607 | BI8: 211412619 | BJ8: - | BK8: 178095094338 | BL8: 210231878448 | BN8: 16131668617 | BO8: - | BQ8: 5420434399 | BR8: - | BS8: 21552103016 | BT8: 231783981464 | BV8: 68245000000 | BW8: - | BX8: 7966266292 | BY8: 53985061075 | BZ8: -541805960 | CA8: - | CB8: 2979069600 | CC8: 132633591006 | CD8: 364417572471 | CF8: February | DQ8: February | DR8: 40015918317 | DT8: -94261888 | DU8: - | DV8: 39921656429 | DZ8: 22392165850 | EA8: 565491000 | EE8: 222005363 | EF8: 1293465 | EG8: 2696948 | EH8: 9049778 | EI8: 1962777 | EJ8: 585879 | EK8: 151539 | EL8: 6637860 | EM8: 36369754 | EO8: 76200000 | EP8: 11241421 | ER8: 364107426 | ES8: 471516569 | ET8: 1997191395 | EV8: 6970489 | EX8: 7791915 | EY8: 84742190 | EZ8: 187134786 | FA8: 30650575 | FC8: 114452204 | FD8: 21982459 | FF8: 20197439 | FG8: 84378 | FI8: 24380000 | FJ8: 35225130 | FO8: 27952102 | FQ8: 82347618 | FR8: 184492750 | FS8: =FR8+FR7 -> 302085750 | FW8: 24500532 | FZ8: 4486900 | GA8: 19373805 | GB8: 9207729 | GC8: 1201085 | GD8: 12357289 | GE8: 31229661 | GF8: 1105871 | GG8: - | GH8: 20950373 | GI8: 250000000 | GM8: 2.7445523e+10 | GQ8: 4000000 | GR8: 56681061 | GS8: - | GT8: 18914000 | GU8: 82255996 | GV8: 48472243 | GW8: 22118501 | GX8: 229723827 | GY8: 481659168 | GZ8: 576797549 | HC8: 40136131 | HG8: 32968534 | HH8: 56737782 | HI8: - | HJ8: 37096158 | HK8: 7781025 | HN8: 2502709 | HO8: 35489846 | HP8: 4684000 | HQ8: 214327216 | HR8: 21534650 | HS8: 3231689 | HT8: 61822374 | HU8: 1400000 | HV8: 789750 | HW8: 112500000 | HX8: 91330954 | HY8: 9333482 | HZ8: 6572150 | IA8: 7373650 | IB8: 2434999 | IC8: 15796111 | ID8: 28890637 | IE8: 10281010 | IF8: 5205461 | IG8: 9486225 | IH8: 2550000 | IK8: 17500000 | IL8: 545613 | IM8: 101436998 | IO8: 500000 | IQ8: 160000 | IU8: 10256410 | JB8: 10000000 | JE8: 1100000 | JH8: 7339144 | JI8: 5780000 | JK8: 27600000 | JM8: 499749540 | JN8: 27556938 | JO8: 6302090 | JP8: 42861456 | JQ8: 5700000 | JR8: 4500000 | JS8: 24915000 | JT8: 3.1366821e+15 | JW8: 841310075 | JX8: 45296000 | JY8: 57581644000000 | JZ8: 944187719 | KC8: 5467002 | KD8: 5467002 | KG8: 10402432 | KH8: 7524000000000 | KI8: 328712547 | KJ8: 250000 | KK8: 505 | KM8: 4954955 | KN8: 351844439 | KQ8: 9113718 | KR8: 1735588517 | KT8: 93666662 | KV8: 632176029 | KW8: 1881 | KZ8: 450000000 | LC8: 3700000 | LE8: 2924246807 | LH8: 120515 | LI8: 120515 | LJ8: =LE8+KD8+JZ8+JT8 -> 3.13669e+15
A9: March | B9: 48178814422 | C9: 40934719757 | D9: 7244094665 | F9: 3260324202 | G9: 1314214864 | H9: 37721614 | I9: 4612260680 | J9: 2631833985 | L9: 168954351 | M9: 2176414214 | N9: -2007459863 | P9: 624374122 | Q9: 5800 | S9: 5800 | T9: 624368322 | W9: 0 | X9: 624368322 | AD9: 19442003776 | AE9: 51173068869 | AG9: -325897486 | AH9: 10482259154 | AI9: 92350283616 | AJ9: - | AL9: 20785426853 | AM9: 12225997754 | AN9: 206133142535 | AP9: - | AQ9: 130908524708 | AR9: 6648934098 | AU9: 1712002768 | AV9: 139269461574 | AW9: 345402604109 | BA9: 12535565229 | BC9: - | BD9: - | BE9: 5495911745 | BF9: 1887033524 | BI9: 123728456 | BJ9: - | BK9: 171105117438 | BL9: 191147356392 | BN9: 16098725935 | BO9: - | BP9: - | BQ9: 4874363998 | BR9: - | BS9: 20973089933 | BT9: 212120446325 | BV9: 68245000000 | BW9: - | BX9: 8614100314 | BY9: 53985793831 | BZ9: -541805960 | CA9: - | CB9: 2979069600 | CC9: 133282157785 | CD9: 345402604110 | CF9: March | DQ9: March | DR9: 48182107568 | DT9: -1115999 | DU9: -3600543 | DV9: 48177391026 | DZ9: 36906890058 | EA9: 31458000 | EE9: 215442863 | EF9: - | EG9: 5130400 | EH9: 398352 | EI9: 3630631 | EJ9: 5510499 | EK9: - | EL9: 9055099 | EM9: 36433869 | EO9: 78400000 | EP9: -2422384 | ER9: 330448692 | ES9: 563827103 | ET9: 1528774325 | EV9: 25221158 | EX9: 13299998 | EY9: 77156083 | EZ9: 170169077 | FA9: 3773210 | FC9: 157610005 | FD9: 22715808 | FF9: 32680371 | FG9: 45824 | FI9: 13200000 | FJ9: 20648075 | FO9: 19046250 | FQ9: 73863657 | FR9: 119704190 | FV9: 7693670 | FW9: 185886522 | FX9: 6500000 | FZ9: 2684750 | GA9: 72003354 | GB9: 5476718 | GC9: 224912 | GD9: 1129129 | GE9: 147272109 | GF9: 1870334 | GG9: - | GH9: 15311504 | GI9: - | GJ9: 2738184 | GM9: 40910902400 | GQ9: 188800 | GR9: 56681061 | GS9: 2055234 | GT9: 22576264 | GU9: 73328439 | GV9: 48404667 | GW9: 22118501 | GX9: 229723827 | GY9: 445721520 | GZ9: 501341795 | HC9: 41860616 | HF9: 235397436 | HG9: 31292115 | HH9: 58584781 | HI9: 570000 | HJ9: 30057426 | HK9: 40058503 | HN9: 2502709 | HO9: 29369114 | HP9: 2644500 | HQ9: 392268968 | HR9: 18255000 | HS9: 471200 | HT9: 39740733 | HU9: 37450000 | HV9: - | HW9: - | HX9: 14184500 | HY9: 2683373 | HZ9: 13066896 | IA9: 1665600 | IB9: 459000 | IC9: 24062775 | ID9: 28386565 | IE9: 11264468 | IF9: 4662225 | IG9: 20609000 | IH9: 3000000 | IK9: - | IL9: 1136720 | IM9: 145217360 | IO9: - | IQ9: - | IT9: 3153153 | IU9: - | JB9: 12150000 | JE9: - | JH9: 7339144 | JI9: - | JK9: - | JM9: 448420497 | JN9: 39472443000000 | JO9: 9443310 | JP9: 45879584 | JQ9: 44124797 | JR9: 9000000 | JS9: 8102500000000 | JT9: 3260147119 | JW9: 1112854406 | JX9: 144000000 | JY9: 57360458 | JZ9: 1314214864 | KC9: 37721614 | KD9: 37721614 | KG9: 10529676 | KH9: 6234595 | KI9: 152223945 | KJ9: - | KK9: 600 | KM9: 1388801 | KN9: 170377617 | KQ9: 9314146 | KR9: 1622930028 | KT9: 93666662 | KV9: - | KW9: 640203 | KY9: 400407 | KZ9: 450000000 | LC9: - | LE9: 2176951445 | LH9: 939175 | LI9: 939175 | LJ9: =LE9+KD9+JZ9+JT9 -> 6789035042
A10: April | B10: 29575707285 | C10: 22158325998 | D10: 7417381287 | F10: 3742450493 | G10: 512771636 | H10: 45975500 | I10: 4301197629 | J10: 3116183658 | L10: 466038804 | M10: 2337754847 | N10: -1871716042 | P10: 1244467616 | Q10: 7073168 | S10: 7073168 | T10: 1237394448 | W10: 0 | X10: 1237394448 | AD10: 22149448688 | AE10: 39387620234 | AG10: -726809713 | AH10: 8069303618 | AI10: 99484397378 | AJ10: - | AL10: 42184427546 | AM10: 13027126905 | AN10: 223575514655 | AP10: - | AQ10: 130729959005 | AR10: 7117825212 | AU10: 3097471000 | AV10: 140945255216 | AW10: 364520769872 | BA10: 13754261151 | BC10: - | BD10: - | BE10: 5190026785 | BF10: 2875451223 | BI10: 204767964 | BJ10: - | BK10: 186931451312 | BL10: 208955958435 | BN10: 15378310047 | BQ10: 10699500880 | BR10: - | BS10: 26077810927 | BT10: 235033769362 | BV10: 68245000000 | BW10: - | BX10: 9828369801 | BY10: 50176612716 | BZ10: -3110625307 | CA10: - | CB10: 4347643300 | CC10: 129487000509 | CD10: 364520769872 | CF10: April | DQ10: April | DR10: 29612451591 | DT10: -3070219 | DU10: -33674087 | DV10: 29575707285 | DZ10: 21523784259 | EA10: - | EE10: 239260219 | EF10: 1836691 | EG10: 2481691 | EH10: 7725793 | EI10: 879241 | EJ10: 312254 | EK10: 28846 | EL10: 4071356 | EM10: 35630504 | EO10: 49700000 | EP10: -19826732 | ER10: 324285484 | ES10: 307270932 | ET10: 1524741357 | EV10: 8997500 | EX10: 19511377 | EY10: 77483483 | EZ10: 156527580 | FA10: 7819930 | FC10: 78075299 | FD10: 20153339 | FF10: 684320 | FG10: 2286123 | FI10: 36480000 | FJ10: 31218950 | FN10: 660000 | FO10: 21235165 | FQ10: 5191495 | FR10: 267015399 | FV10: 23405000 | FW10: - | FX10: 15855186 | FZ10: 31200000 | GA10: 52362704 | GB10: 4800987 | GC10: 9545738 | GD10: -4498687 | GE10: 21637108 | GF10: 3371528 | GG10: 3100000 | GH10: 144510 | GI10: - | GJ10: 1479062 | GK10: 155839622 | GM10: 25053764614 | GQ10: 50395000 | GR10: 56681061 | GS10: 1096819 | GT10: 36840668 | GU10: 73328439 | GV10: 47894073 | GW10: 22118501 | GX10: 229723827 | GY10: 375241484 | GZ10: 492273124 | HC10: 32132452 | HF10: 186983075 | HG10: 31768205 | HH10: 57841930 | HI10: - | HJ10: 38906770 | HK10: 1871953 | HN10: 2502709 | HO10: 40696542 | HP10: 6577600 | HQ10: 367767840 | HR10: 7417000 | HS10: 2095000 | HT10: 254236581 | HU10: 2600000 | HV10: - | HW10: - | HX10: 23666755 | HY10: 12353040 | HZ10: 20116987 | IA10: 13879458 | IB10: 2493500 | IC10: 27819907 | ID10: 42647927 | IE10: 10217530 | IF10: 3257979 | IG10: 14755231 | IH10: 6850801 | IK10: - | IL10: - | IM10: 144930939 | IN10: 219782308 | IO10: - | IP10: 100201552 | IQ10: - | IS10: 20512326 | IT10: 14653153 | IU10: - | IX10: 17975000 | JB10: 5922000 | JE10: 330309 | JH10: 7339144000000 | JI10: - | JK10: 7175000 | JM10: 517391900 | JN10: - | JO10: 2127511000000 | JP10: 40902917 | JQ10: 10416666 | JR10: 4500000 | JS10: 31240000 | JT10: 3742450493 | JW10: 423608954 | JX10: 21000000 | JY10: 68162682 | JZ10: 512771636 | KC10: 45975500 | KD10: 45975500 | KG10: 14962478 | KH10: 5964500 | KI10: 443109689 | KJ10: 2000000 | KK10: 2137 | KM10: - | KN10: 466038804 | KQ10: 11342866 | KR10: 1666356554 | KT10: 99369633 | KV10: - | KW10: 2065 | KX10: 10611228 | KZ10: 550000000 | LC10: - | LE10: 2337682345 | LH10: 7073168 | LI10: 7073168 | LJ10: =LE10+KD10+JZ10+JT10 -> 6638879974
A11: May | B11: 28480547642 | C11: 19037629900 | D11: 9442917742 | F11: 4097901831 | G11: 424604784 | H11: 14616902 | I11: 4537123517 | J11: 4905794225 | L11: 935138038 | M11: 2473379589 | N11: -1538241551 | P11: 3367552675 | Q11: 3845 | S11: 3845 | T11: 3367548830 | W11: 0 | X11: 3367548830 | AD11: 25811037262 | AE11: 47008967012 | AG11: -726809713 | AH11: 7289928852 | AI11: 105118264727 | AJ11: - | AL11: 35666207828 | AM11: 14770319852 | AN11: 234937915819 | AP11: - | AQ11: 131006355933 | AR11: 7088722766 | AU11: 3097471000 | AV11: 141192549699 | AW11: 376130465518 | BA11: 22160497551 | BC11: - | BD11: - | BE11: 7273003713 | BF11: 1170365530 | BI11: 209126689 | BJ11: - | BK11: 201773311160 | BL11: 232586304644 | BN11: - | BQ11: 10689684037 | BR11: - | BS11: 10689684037 | BT11: 243275988681 | BV11: 68245000000 | BW11: - | BX11: 13195846129 | BY11: 50176612716 | BZ11: -3110625307 | CA11: - | CB11: 4347643300 | CC11: 132854476837 | CD11: 376130465518 | CF11: May | DQ11: May | DR11: 28705068315 | DT11: -3554196 | DU11: -220966477 | DV11: 28480547642 | DZ11: 15297472610 | EA11: 6335000 | EE11: 241470269 | EF11: 7893570 | EG11: 23588612 | EH11: 3967052 | EI11: 5338824 | EJ11: 12976311 | EK11: 13263163 | EL11: 11046185 | EM11: 36158762 | EO11: 46500000 | EP11: 53799097 | ER11: 331196306 | ES11: 73039394 | ET11: 1272103653 | EV11: 8752500 | EX11: 67119160 | EY11: 81128729 | EZ11: 166385566 | FA11: 51803988 | FC11: 143239832 | FD11: 27391726 | FF11: 3470445 | FG11: - | FI11: 12870000 | FJ11: 28346753 | FN11: - | FO11: 11362655 | FQ11: 10140738 | FR11: 180113477 | FV11: 60479625 | FW11: 132298674 | FX11: - | FZ11: 6254458 | GA11: 76165543 | GB11: 7421789 | GC11: 2440212 | GD11: 1547331 | GE11: 264207721 | GF11: 6630000 | GG11: - | GH11: - | GI11: 250500000 | GJ11: 1410168 | GK11: - | GM11: 19037629900 | GQ11: 49425481 | GR11: 620937378 | GS11: - | GT11: 34072300 | GU11: 73328439 | GV11: 48780029 | GW11: 22118501 | GX11: 229723827 | GY11: 424978646 | GZ11: 437607566 | HC11: 20723838 | HF11: 182483070 | HG11: 32401245 | HH11: 60872712 | HI11: 1495000 | HJ11: 38919265 | HK11: 153153 | HN11: 2502709 | HO11: 42962572 | HP11: 3092549 | HQ11: 387891565 | HR11: 4422601 | HS11: 6264262 | HT11: 98612811 | HU11: 23925000 | HV11: - | HW11: - | HX11: 77690444 | HY11: 10424848 | HZ11: 11335522 | IA11: 1271660 | IB11: 369200 | IC11: 7169400 | ID11: 10855249 | IE11: 13059808 | IF11: 5984394 | IG11: 24511000 | IH11: 13869351 | IK11: 2200000 | IL11: 425978 | IM11: 94163039 | IN11: 76673615 | IO11: - | IP11: 101178352 | IQ11: - | IS11: 3064288 | IT11: 11500000 | IU11: 110000000 | IX11: 8400000 | JB11: 20750000 | JE11: 1375000 | JH11: 7339144000000 | JI11: 3631104 | JK11: - | JM11: 506580138 | JN11: - | JO11: 11976274000000 | JP11: 43039505 | JQ11: 48307500 | JR11: 4500000 | JS11: 18562500 | JT11: 4097901831 | JW11: 333049075 | JX11: 17000000 | JY11: 74555709 | JZ11: 424604784 | KC11: 14616902 | KD11: 14616902 | KG11: 8597604 | KH11: 6489000 | KI11: 873214712 | KJ11: 46826500 | KK11: 10222 | KN11: 935138038 | KQ11: 9521123 | KR11: 1809093898 | KT11: 136745000 | KV11: 0 | KW11: 4866 | KY11: 2719701 | KZ11: 350000000 | LB11: 165295000 | LC11: - | LE11: 2473379589 | LH11: 3845 | LI11: 3845 | LJ11: =LE11+KD11+JZ11+JT11 -> 7010503106
A12: June | B12: 43859289220 | C12: 35299745158 | D12: 8559544062 | F12: 3914387840 | G12: 864961390 | H12: 80087700 | I12: 4859436930 | J12: 3700107132 | L12: 32493074 | M12: 2679452410 | N12: -2646959337 | P12: 1053147795 | Q12: 234133 | S12: 234133 | T12: 1052913662 | W12: 0 | X12: 1052913662 | AD12: 15936203293 | AE12: 63024226276 | AG12: -726809713 | AH12: 6595645696 | AI12: 107226471817 | AJ12: - | AL12: 38703370451 | AM12: 15350769281 | AN12: 246109877102 | AP12: - | AQ12: 130656345348 | AR12: 7059265121 | AU12: 3097471000 | AV12: 140813081470 | AW12: 386922958571 | BA12: 25476188216 | BC12: - | BD12: - | BE12: 8090627462 | BF12: 2283637018 | BI12: 215394159 | BJ12: - | BK12: 190885058208 | BL12: 226950905064 | BN12: 15399414819 | BQ12: 10665248189 | BR12: - | BS12: 26064663008 | BT12: 253015568072 | BV12: 68245000000 | BW12: - | BX12: 14248759791 | BY12: 50176612716 | BZ12: -3110625307 | CA12: - | CB12: 4347643300 | CC12: 133907390499 | CD12: 386922958571 | CF12: June | DQ12: June | DR12: 43875803190 | DT12: -10259733 | DU12: -6254236 | DV12: 43859289220 | DZ12: 27625035430 | EA12: 280808000 | EE12: 243995015 | EF12: 9016711 | EG12: 17625038 | EH12: 6193448 | EI12: 5720096 | EJ12: 8043401 | EK12: 992869 | EL12: 15764194 | EM12: 35768495 | EO12: 24000000 | EP12: 30140821 | ER12: 362932721 | ES12: 198159822 | ET12: 4841632676 | EV12: 21186500 | EX12: 41036519 | EY12: - | EZ12: 180899238 | FA12: 38614167 | FC12: 79502761 | FD12: 22991127 | FF12: 153693704 | FG12: - | FI12: 24299000 | FJ12: 35969640 | FN12: - | FO12: 15240780 | FQ12: 8184950 | FR12: 162238183 | FV12: 241525917 | FW12: 41643300 | FX12: - | FZ12: - | GA12: 83001413 | GB12: 14290078 | GC12: 2769738 | GD12: 11825996 | GE12: 25599080 | GF12: - | GG12: - | GH12: 11424493 | GI12: - | GJ12: - | GK12: - | GM12: 34921765318 | GQ12: 44802216 | GR12: 767671959 | GS12: 2826500 | GT12: 26933742 | GU12: 73510730 | GV12: 48642940 | GW12: 22118501 | GX12: 230603147 | GY12: 416873395 | GZ12: 493031932 | HC12: 44722423 | HF12: 182483070 | HG12: 31942268 | HH12: 71962120 | HI12: 850000 | HJ12: 31451175 | HK12: 750000 | HN12: 3985525 | HO12: 80430233 | HP12: 4980568 | HQ12: 268841798 | HR12: 4826207 | HS12: 3162199 | HT12: 102279477 | HU12: 27250000 | HV12: - | HW12: 87500000 | HX12: 17246000 | HY12: 9814528 | HZ12: 15096782 | IA12: 1948920 | IB12: 1197000 | IC12: 20102905 | ID12: 11214164 | IE12: 12549678 | IF12: 4027822 | IG12: 27666984 | IH12: 13801601 | IK12: - | IL12: 133329 | IM12: 138553424 | IN12: 32088251 | IO12: 24967315 | IP12: 100201552 | IQ12: 500000 | IS12: - | IT12: 42792793 | IU12: - | IX12: - | JB12: 20750000 | JE12: - | JH12: 7339144000000 | JI12: 5643250 | JK12: - | JM12: 516328291 | JN12: - | JO12: 11695317000000 | JP12: 43039505 | JQ12: 48307500 | JR12: - | JS12: 78929500 | JT12: 4280367681 | JW12: 802928692 | JX12: 19000000 | JY12: 43032698 | JZ12: 864961390 | KC12: 92087700 | KD12: 92087700 | KG12: 25381773 | KH12: 7097500 | KI12: 0 | KJ12: - | KK12: 13801 | KN12: 32493074 | KQ12: 8479013 | KR12: 1837214256 | KT12: 209500000 | KV12: 23996341 | KW12: 4139 | KX12: 5639102 | KZ12: 585245310 | LB12: 9374250 | LC12: - | LE12: 2679452410 | LH12: 234133 | LI12: 234133 | LJ12: =LE12+KD12+JZ12+JT12 -> 7916869181
A13: July | B13: 60848462285 | C13: 45952511554 | D13: 14895950731 | F13: 3979410847 | G13: 490049564 | H13: 106413011 | I13: 4575873422 | J13: 10320077309 | L13: 189156082 | M13: 1969173360 | N13: -1780017277 | P13: 8540060032 | Q13: 0 | S13: 0 | T13: 8540060032 | W13: 0 | X13: 8540060032 | AD13: 16228480826 | AE13: 82925685482 | AG13: -726809713 | AH13: 5825645696 | AI13: 99274743635 | AJ13: - | AL13: 33662234090 | AM13: 16997370821 | AN13: 254187350837 | AP13: - | AQ13: 132943952489 | AR13: 7029807476 | AU13: 3097471000 | AV13: 143071230966 | AW13: 397258581802 | BA13: 30921952568 | BC13: - | BD13: - | BE13: 11493763808 | BF13: 1395353998 | BI13: 214849468 | BJ13: - | BK13: 184742012601 | BL13: 228767932443 | BN13: 15401214441 | BQ13: 10641984387 | BR13: 0 | BS13: 26043198828 | BT13: 254811131271 | BV13: 68245000000 | BW13: 0 | BX13: 22788819822 | BY13: 50176612716 | BZ13: -3110625307 | CA13: - | CB13: 4347643300 | CC13: 117878613431 | CD13: 397258581802 | CF13: July | DQ13: July | DR13: 61121035296 | DT13: -29599501 | DU13: -242973510 | DV13: 60848462285 | DZ13: 38819880826 | EA13: 510959000 | EE13: 245695016 | EF13: 15656850 | EG13: 15026082 | EH13: 20455738 | EI13: 25428453 | EJ13: 23261444 | EK13: 1632153 | EL13: 6791720 | EM13: 35262639 | EO13: 48000000 | EP13: 233025586 | ER13: 392674443 | ES13: 498481549 | ET13: 3842897501 | EV13: 51100086 | EX13: 32132359 | EY13: 61109089 | EZ13: 188776392 | FA13: 15331056 | FC13: 114019783 | FD13: 21562472 | FF13: 45712333 | FG13: - | FI13: 12366000 | FJ13: 21126300 | FN13: - | FO13: 22645650 | FQ13: 1874378 | FR13: 164005615 | FV13: 15153000 | FW13: 578879 | FX13: - | FZ13: 6763904 | GA13: 261225465 | GB13: 17983486 | GC13: 23229831 | GD13: 3306549 | GE13: 6044978 | GF13: - | GG13: 7125000 | GH13: 15767450 | GI13: - | GJ13: - | GK13: - | GL13: 44012791 | GM13: 45888081847 | GQ13: 68901000 | GR13: 621585711 | GS13: 553118 | GT13: 5106056 | GU13: 73510730 | GV13: 49764655 | GW13: 22118501 | GX13: 230603147 | GY13: 413713990 | GZ13: 438948282 | HC13: 22691807 | HF13: 156942777 | HG13: 34237160 | HH13: 63910762 | HI13: - | HJ13: 16428627 | HK13: - | HN13: 2502709 | HO13: 58650022 | HP13: 5482740 | HQ13: 374057636 | HR13: 11397500 | HS13: 16962527 | HT13: 91112811 | HU13: 473795000 | HV13: - | HW13: 25000000 | HX13: - | HY13: 8223768 | HZ13: 23713013 | IA13: 8691664 | IB13: 3389900 | IC13: 11527700 | ID13: 26160402 | IE13: 12994102 | IF13: 3280525 | IG13: 9590200 | IH13: 12554802 | IK13: 1065709 | IL13: 8182769 | IM13: 139954990 | IN13: 56986631 | IO13: 23807888 | IP13: - | IQ13: 1500000 | IS13: 0 | IT13: 0 | IU13: 0 | IV13: 4250000 | IX13: - | JB13: 74686037 | JE13: 12949832 | JH13: 7339144 | JI13: - | JK13: - | JM13: 526248164 | JN13: - | JO13: 14990068 | JP13: 43039505 | JQ13: - | JR13: - | JS13: 35555000 | JT13: 4348659082 | JW13: 349172664 | JX13: 19000000 | JY13: 121876900 | JZ13: 490049564 | KC13: 106163011 | KD13: 106163011 | KG13: 21438602 | KH13: 16255418 | KI13: 150742199 | KJ13: - | KK13: 719864 | KN13: 189156082 | KQ13: 10020191 | KR13: 1809252863 | KT13: 94500000 | KV13: 0 | KW13: 23632 | KX13: 5376673 | KZ13: 50000000 | LB13: - | LC13: - | LE13: 2158329442 | LH13: 0 | LI13: 0 | LJ13: =LE13+KD13+JZ13+JT13 -> 7103201099
A14: August | B14: 54451094996 | C14: 42772596362 | D14: 11678498634 | F14: 3430273181 | G14: 429591314 | H14: 41150500 | I14: 3901014994 | J14: 7777483640 | L14: 554195179 | M14: 2479326566 | N14: -1925131386 | P14: 5852352253 | Q14: 0 | S14: 0 | T14: 5852352253 | X14: 5852352253 | AD14: 15146534221 | AE14: 95360939306 | AG14: -301516003 | AH14: 4937637296 | AI14: 102352653702 | AL14: 27357562602 | AM14: 16372616426 | AN14: 261226427550 | AP14: - | AQ14: 133732209029 | AR14: 7000349831 | AU14: 3097471000 | AV14: 143830029860 | AW14: 405056457410 | BA14: 26707978354 | BC14: - | BD14: - | BE14: 11154914765 | BF14: 1486038598 | BI14: 215511729 | BJ14: - | BK14: 191571541624 | BL14: 231135985071 | BN14: 15403011497 | BQ14: 10217658058 | BS14: 25620669555 | BT14: 256756654625 | BV14: 68245000000 | BX14: 28641172076 | BY14: 50176612716 | BZ14: -3110625307 | CA14: - | CB14: 4347643300 | CC14: 148299802784 | CD14: 405056457410 | CF14: August | DQ14: August | DR14: 54457721463 | DT14: -2135667 | DU14: -4490800 | DV14: 54451094996 | DZ14: 33668034218 | EA14: 1128546000 | EE14: 251397797 | EF14: 14854646 | EG14: 19894149 | EH14: 7620753 | EI14: 13332757 | EJ14: 100210109 | EK14: 2617095 | EL14: 4602982 | EM14: 46641517 | EO14: 36000000 | EP14: -61427224 | EQ14: 131712554 | ER14: 293098556 | ES14: 398141715 | ET14: 4745953221 | EV14: 4380765 | EX14: 424598482 | EY14: 99713118 | EZ14: 166689519 | FA14: 39358190 | FC14: 130045417 | FD14: 22849475 | FF14: 1936105 | FI14: 13112000 | FJ14: 34164045 | FN14: - | FO14: 23030050 | FQ14: 536884739 | FR14: 198843505 | FV14: 37439350 | FW14: 37102633 | FZ14: 42760219 | GA14: 99662488 | GB14: 4093220 | GC14: 418404 | GD14: 358050 | GE14: 5805170 | GF14: - | GG14: - | GH14: 23837500 | GI14: - | GJ14: - | GK14: - | GL14: 24283074 | GM14: 42772596362 | GQ14: 81273000 | GR14: 226897686 | GS14: - | GT14: 16697200 | GU14: 76213433 | GV14: 50660491 | GW14: 22118501 | GX14: 230603147 | GY14: 413713990 | GZ14: 498218892 | HC14: 29739111 | HF14: 182483070 | HG14: 32333729 | HH14: 63866902 | HI14: - | HJ14: 26383193 | HK14: - | HN14: - | HO14: 34865438 | HP14: 5418960 | HQ14: 192840410 | HR14: 14160340 | HS14: 1522000 | HT14: 86307533 | HU14: 38803136 | HV14: - | HW14: - | HX14: 22555000 | HY14: 5449101 | HZ14: 7972509 | IA14: 15507154 | IB14: 2037500 | IC14: 22754613 | ID14: 21196163 | IE14: 12824140 | IF14: 3803171 | IG14: 12177000 | IH14: 12252901 | IK14: - | IL14: 17534876 | IM14: 140834595 | IN14: 93548441 | IO14: 2019316 | IP14: - | IQ14: 750000 | IS14: - | IT14: 59459460 | IU14: - | IV14: - | IX14: - | JB14: 7800000 | JE14: 3995125 | JH14: 7339144 | JI14: - | JK14: - | JM14: 540948282 | JN14: - | JO14: 6151256 | JP14: 45082292 | JQ14: 5085000 | JR14: 4500000 | JS14: 31575980 | JT14: 3430273181 | JW14: 354467423 | JX14: 25500000 | JY14: 49623891 | JZ14: 429591314 | KC14: 41150500 | KD14: 41150500 | KG14: 22209512 | KH14: 5416500 | KI14: 0 | KJ14: 600000 | KK14: 3011 | KL14: 525966156 | KN14: 554195179 | KQ14: 11245904 | KR14: 1748764402 | KT14: 94500000 | KV14: 208466361 | KW14: 733 | KX14: 4708797 | KZ14: 411640368 | LB14: - | LC14: - | LE14: 3033521745 | LH14: 8123461 | LI14: 8123461 | LJ14: =LE14+KD14+JZ14+JT14 -> 6934536740
A15: September | B15: 73337840528 | C15: 64662165092 | D15: 8675675436 | F15: 3598035874 | G15: 772538953 | H15: 105153610 | I15: 4475728437 | J15: 4199946999 | L15: 247895233 | M15: 2081307655 | N15: -1833412422 | P15: 2366534577 | Q15: 0 | S15: 0 | T15: 2366534577 | X15: 2366534577 | AD15: 26449313884 | AE15: 114222708267 | AF15: 2493348844 | AG15: -135609003 | AH15: 3770977936 | AI15: 86952512893 | AL15: 14449173958 | AM15: 17263915379 | AN15: 265466342159 | AQ15: 135246210726 | AR15: 7089517186 | AU15: 3097471000 | AV15: 145433198911 | AW15: 410899541071 | BA15: 22607963166 | BE15: 12112195121 | BF15: 774032498 | BI15: 196895005 | BK15: 196058597022 | BL15: 231749682812 | BN15: 18272650705 | BQ15: 10210870193 | BS15: 28483520898 | BT15: 260233203709 | BV15: 68245000000 | BX15: 31007706653 | BY15: 50176612716 | BZ15: -3110625307 | CB15: 4347643300 | CC15: 150666337362 | CD15: 410899541071 | CF15: September | DQ15: September | DR15: 73347669895 | DT15: -9829367 | DU15: - | DV15: 73337840528 | DZ15: 56677498576 | EA15: 1036857000 | EE15: 251704392 | EF15: 23150721 | EG15: 25427892 | EH15: 21258556 | EI15: 2972007 | EJ15: 16387369 | EK15: 3465669 | EL15: 3922615 | EM15: 45934749 | EO15: 51300000 | EP15: -14779849 | EQ15: -154622342 | ER15: 400344914 | ES15: 164151853 | ET15: 3918492440 | EV15: 2251463 | EX15: 441686286 | EY15: 66118656 | EZ15: 193386598 | FA15: 26548102 | FC15: 161142952 | FD15: 17385132 | FF15: 12686228 | FG15: 19793750 | FI15: 25620000 | FJ15: 23021600 | FN15: - | FO15: 31838450 | FQ15: 26529465 | FR15: 327194523 | FV15: 31612500 | FW15: 211794735 | FX15: - | FZ15: - | GA15: 341903388 | GB15: 1123287 | GC15: 1852507 | GD15: 45868316 | GE15: 131448993 | GF15: 9251766 | GG15: 3000000 | GH15: 15723478 | GI15: - | GJ15: 783784 | GK15: - | GL15: 19132570 | GM15: 64662165092 | GQ15: 57307672 | GR15: 225503814 | GS15: 512160 | GT15: 16157500 | GU15: 76213433 | GV15: 50865801 | GW15: 22118501 | GX15: 231299121 | GY15: 413713990 | GZ15: 431916587 | HC15: 27674988 | HF15: 182483070 | HG15: 32887720 | HH15: 64016678 | HI15: 80000 | HJ15: 17559599 | HK15: - | HL15: 3750000 | HN15: - | HO15: 56732398 | HP15: 4424560 | HQ15: 222767892 | HR15: 9068265 | HS15: 39529492 | HT15: 84807533 | HU15: 12100000 | HV15: - | HW15: 5000000 | HX15: - | HY15: 9177029 | HZ15: 23926555 | IA15: 289750 | IB15: 782500 | IC15: 20408952 | ID15: 13942881 | IE15: 11586534 | IF15: 3597400 | IG15: 34455300 | IH15: - | IK15: - | IL15: 2091245 | IM15: 135116602 | IN15: 32088251 | IO15: 76500000 | IP15: - | IQ15: - | IS15: - | IT15: 23243244 | IU15: - | IV15: - | IX15: 261835000 | JB15: 14892216 | JE15: 0 | JH15: 7339144 | JK15: - | JM15: 528255203 | JN15: - | JO15: 22747845 | JP15: 47782450 | JQ15: - | JR15: 4500000 | JS15: 34987000 | JT15: 3598035874 | JW15: 535244435 | JX15: 121500000 | JY15: 115794518 | JZ15: 772538953 | KC15: 105153610 | KD15: 105153610 | KG15: 23675180 | KH15: 168562079 | KI15: 55013037 | KJ15: 600000 | KK15: 44937 | KL15: - | KN15: 247895233 | KQ15: 16354921 | KR15: 1896955018 | KT15: 94500000 | KV15: 0 | KW15: 1848 | KX15: 4137519 | KZ15: 50000000 | LB15: - | LC15: 19358348 | LE15: 2081307655 | LH15: 0 | LI15: 0 | LJ15: =LE15+KD15+JZ15+JT15 -> 6557036092
A16: October | CF16: October | DQ16: October | LJ16: =LE16+KD16+JZ16+JT16 -> 0
A17: November | CF17: November | DQ17: November | LJ17: =LE17+KD17+JZ17+JT17 -> 0
A18: December | CF18: December | DQ18: December | LJ18: =LE18+KD18+JZ18+JT18 -> 0
A21: Laba Rugi Konsolidasi up to month X in 2026 | AB21: Neraca Konsolidasi up to month x in 2026 | CF21: Arus Kas Konsolidasi up to month X in 2026 | DQ21: Monthly CALK Konsolidasi up to month X 2026
B22: Penjualan | C22: Harga Pokok Penjualan | D22: Laba Kotor | E22: Beban Usaha | F22: Beban Umum dan Administrasi | G22: Beban Penjualan dan Pemasaran | H22: Beban Analisa Lab | I22: Jumlah Beban Usaha | J22: Laba Usaha | K22: Pendapatan (Beban) Lain-lain | L22: Pendapatan Lain-lain | M22: Beban Diluar Usaha Lainnya | N22: Jumlah Pendapatan (Beban) Lain-lain | P22: Laba Sebelum Pajak | Q22: Beban Pajak Penghasilan | R22: Pajak tangguhan | S22: Jumlah Beban Pajak | T22: Laba Bersih Setelah Pajak | U22: Penghasilan Komprehensif Lain | V22: Keuntungan/Kerugian aktuarial | W22: atas liabilitas imbalan kerja | X22: Jumlah Penghasilan (Rugi) Komprehensif Lain | AB22: ASET | AC22: Aset Lancar | AD22: Kas dan Setara Kas | AE22: Piutang Usaha | AF22: Anjak Piutang | AG22: Cadangan Kerugian Piutang Tak Tertagih | AH22: Piutang Lain Pihak Terkait | AI22: Persediaan | AJ22: Persediaan dalam Proses | AK22: Persediaan Barang Dagang | AL22: Biaya Dibayar Dimuka | AM22: Pajak Dibayar Dimuka | AN22: Jumlah Aset Lancar | AO22: Aset Tidak Lancar | AP22: Investasi | AQ22: Aset Tetap | AR22: Aset Tidak Lancar Lainnya | AU22: Aset Pajak Tangguhan | AV22: Jumlah Aset Tidak Lancar | AW22: Jumlah Aset | AY22: LIABILITAS DAN EKUITAS | AZ22: Liabilitas Lancar | BA22: Hutang Usaha | BC22: Barang yang belum terinvoice | BD22: Persediaan Barang Diterima Belum di BAST (LPB) | BE22: Hutang Pajak | BF22: Uang Muka Penjualan | BI22: Hutang Lain-Lain | BJ22: Hutang Bunga Bank | BK22: Hutang Bank Jangka Pendek | BL22: Jumlah Liabilitas Lancar | BM22: Liabilitas Tidak Lancar | BN22: Hutang Bank Jangka Panjang | BO22: Hutang Leasing | BP22: Hutang Pemegang Saham | BQ22: Hutang Imbalan Pasca Kerja | BR22: Liabilitas pajak tangguhan | BS22: Jumlah Liabilitas Tidak Lancar | BT22: Jumlah Liabilitas | BU22: Ekuitas | BV22: Modal Disetor | BW22: Saldo Laba | BX22: Laba-Rugi Periode Berjalan | BY22: Laba-Rugi Ditahan | BZ22: Akumulasi penghasilan komprehensif lain | CA22: Kepentingan non pengendali - Rugi/Laba | CB22: Kepentingan non pengendali - Modal | CC22: Jumlah Ekuitas | CD22: Jumlah Liabilitas dan Ekuitas | CG22: Arus Kas dari Aktivitas Operasi | CH22: Laba (rugi) bersih | CI22: Penyesuaian : | CJ22: Penyusutan | CK22: Akumulasi Komprehensif Lain | CM22: Penurunan (Kenaikan) : | CN22: Piutang usaha | CO22: Anjak Piutang | CP22: Piutang Afiliasi & Lainnya | CQ22: Biaya dibayar dimuka | CR22: Pajak dibayar dimuka | CS22: Persediaan | CT22: Kenaikan (Penurunan) : | CU22: Utang Usaha | CV22: Hutang Afiliasi & Lainnya | CW22: Utang Pajak | CX22: Uang Muka Penjualan | CY22: Biaya yg masih harus dibayar | CZ22: Hutang jangka Panjang | DA22: Kas Bersih yang digunakan untuk Aktivitas Operasi | DB22: Arus Kas dari Aktivitas Investasi : | DC22: (Penambahan) Pengurangan Aset Tetap | DD22: (Penambahan) Pengurangan Investasi | DE22: (Penambahan) Pengurangan Konstruksi Dalam Pengerjaan | DF22: Kas Bersih yang diperoleh/ digunakan untuk Aktivitas Investasi | DG22: Arus Kas dari Aktivitas Pendanaan : | DH22: Utang Bank | DI22: Modal di setor | DJ22: Kas Bersih yang diperoleh/ digunakan untuk Aktivitas Pendanaan | DK22: Kenaikan Kas & Setara Kas | DL22: Kas & Setara Kas awal periode | DM22: Kas & Setara Kas akhir periode | DR22: Penjualan | DT22: Retur Penjualan | DU22: Diskon Penjualan | DV22: Jumlah Penjualan | DX22: BEBAN POKOK PENJUALAN | DY22: Harga Pokok Penjualan Afiliasi | DZ22: Harga Pokok Penjualan Non Afiliasi | EA22: Beban Bea Masuk Import | EE22: Beban Penyusutan Mesin | EF22: Beban Pemeliharaan Mesin Ew | EG22: Beban Pemeliharaan Mesin Line 1 | EH22: Beban Pemeliharaan Mesin Line 2 | EI22: Beban Pemeliharaan Mesin Line 3 | EJ22: Beban Pemeliharaan Mesin Line 4 | EK22: Beban Pemeliharaan Mesin Line 5 | EL22: Beban Pemeliharaan Mesin Copper Sulphate | EM22: Beban Penyusutan Peralatan Pabrik | EO22: Beban Sewa Kendaraan | EP22: Selisih Stock Opname | ER22: Beban Tenaga Kerja Langsung | ES22: Beban Transportasi Bahan Baku | ET22: Beban Transportasi Produk Jadi | EU22: Beban Transportasi Produk Jadi (Bonus dan Fee Marketing) | EV22: Beban Pemeliharaan Kendaraan Pabrik | EW22: Beban Pemeliharaan Aset Pabrik | EX22: Beban Rumah Tangga Pabrik | EY22: Beban Gaji Staff Pabrik | EZ22: Beban Tenaga Kerja Tidak Langsung | FA22: Beban Pemeliharaan Mesin Pramaterial | FC22: Beban Listrik Pabrik | FD22: Beban Listrik Pabrik (Gudang Timur) | FF22: Beban Transportasi Lainnya | FG22: Beban Perlengkapan Pabrik | FI22: Beban Bbm Pabrik | FJ22: Beban Bongkar | FK22: Beban Qc Produk | FL22: Beban Transportasi Impor | FM22: Beban Gudang Pelabuhan | FN22: Beban Administrasi Pabean | FO22: Beban Muat | FQ22: Beban Klaim | FR22: Beban Gaji PHL | FV22: Beban Asuransi Pengiriman | FW22: Beban Sample | FX22: Beban Demplot | FZ22: Beban Pemeliharaan Bangunan Pabrik | GA22: Beban Pemeliharaan Sarana Prasarana Pabrik | GB22: Beban Perlengkapan Mekanik | GC22: Beban Perlengkapan Elektrikal | GD22: Beban Pemeliharaan Mesin Crf | GE22: Beban Riset Dan Percobaan Lapangan | GF22: Beban Pemeliharaan Mesin Copper Sulphate Line 2 | GG22: Beban Pemeliharaan Aset Lab | GH22: Beban Operasional Gudang | GI22: Beban Uji Dosis (Internal) | GJ22: Beban Perlengkapan Lab | GK22: Beban Kerugian Bibit Afkir | GL22: Beban Pemeliharaan Mesin NPK | GM22: Jumlah Harga Pokok Penjualan | GO22: BEBAN UMUM DAN ADMINISTRASI | GQ22: Beban Pelatihan | GR22: Beban Pelatihan Internal | GS22: Beban Perlengkapan Kantor | GT22: Beban Hse | GU22: Beban Penyusutan Kendaraan | GV22: Beban Penyusutan Inventaris Kantor | GW22: Beban Amortisasi Ditangguhkan SHGB | GX22: Beban Penyusutan Bangunan | GY22: Beban Gaji BOD | GZ22: Beban Gaji Staff Kantor | HC22: Tunjangan Lembur | HF22: Tunjangan Hari Raya - THR | HG22: Beban Asuransi - BPJS KES | HH22: Beban Asuransi - BPJS TK | HI22: Beban Pemeliharaan Aset Kantor | HJ22: Beban Rumah Tangga Kantor | HK22: Beban Pengembangan System/Software | HL22: Beban Kompensasi Ganti Rugi | HM22: Beban Koreksi Fiskal | HN22: Beban Asuransi Kebakaran | HO22: Beban Pemeliharaan Kendaraan Kantor | HP22: Beban Bbm Kantor | HQ22: Beban Perjalanan Dinas Kantor | HR22: Beban Perjalanan Dinas Tamu | HS22: Beban Obat/Pengobatan | HT22: Beban Sewa | HU22: Biaya Legal Dan Perijinan | HV22: Beban Rakor | HW22: Beban Audit | HX22: Beban Perayaan Hari Besar | HY22: Beban Atk Kantor | HZ22: Beban Internet/Vsat | IA22: Beban Cetak/Fotocopy | IB22: Beban Air Minum Kantor | IC22: Beban Konsumsi Dan Oleh-Oleh Tamu | ID22: Beban Kirim Paket (Sampel/Dokumen) | IE22: Beban Listrik Kantor | IF22: Beban Telepon Kantor | IG22: Pajak Kendaraan & PBB | IH22: Beban Suka/Duka | IK22: Beban Pph 4 Ayat 2 | IL22: Beban Pph Pasal 23 | IM22: Beban Pph Pasal 21 | IN22: Beban Pph 25 | IO22: Beban Pinalti Pajak | IP22: Beban Pph Pasal 29 | IQ22: Beban Olahraga Dan Rekreasi | IR22: Biaya Kaizen | IS22: Beban Pemutusan Hubungan Kerja | IT22: Beban Apraisal | IU22: Beban Konsultan Keuangan | IV22: Beban Bphtb | IW22: Beban Kerugian Investasi | IX22: Beban Apresiasi Karyawan | IY22: Beban Imbalan Pasca Kerja | IZ22: Beban Notaris | JA22: Beban Gaji Staff Laboratorium | JB22: Beban Csr (Corporate Social Responsibility) | JC22: Beban Cadangan Kerugian Piutang Tak Tertagih | JD22: Beban Brand Development | JE22: Beban Ppn Tidak Bisa Dikreditkan | JH22: Beban Penyusutan Software | JI22: Beban Rekrutmen | JJ22: Beban Rups | JK22: Beban Aktuaria | JL22: Beban Riset Corporate & Strategy | JM22: Beban Gaji Managemen | JN22: Beban Gaji Principal | JO22: Beban Sarana Prasarana Kantor | JP22: Beban Outsourcing | JQ22: Biaya Pemeliharaan Bangunan Kantor | JR22: Beban Beasiswa | JS22: Beban Kesejahteraan Karyawan | JT22: Jumlah Beban Administrasi dan Umum | JV22: BEBAN PENJUALAN DAN PEMASARAN | JW22: Beban Operasional Pemasaran | JX22: Beban Relasi | JY22: Beban Promosi | JZ22: Jumlah Beban Penjualan dan Pemasaran | KB22: BEBAN ANALISA LAB | KC22: Beban Analisa Lab | KD22: Jumlah Analisa Lab | KF22: PENDAPATAN | KG22: Pendapatan Jasa Giro | KH22: Pendapatan Lain-Lain | KI22: Pendapatan Selisih Lebih Kurs | KJ22: Pendapatan Aval | KK22: Pendapatan Selisih Koma | KL22: Pendapatan Klaim | KM22: Pendapatan Jasa Maklon | KN22: Jumlah Pendapatan | KP22: BEBAN DILUAR USAHA | KQ22: Beban Adm Bank | KR22: Beban Marjin Pinjaman | KT22: Beban Administrasi Kredit - Mk | KV22: Beban Selisih Kurang Kurs | KW22: Beban Selisih Koma | KX22: Beban Market Place | KY22: Beban Lain-Lain | KZ22: Beban Zakat | LB22: Beban Qurban | LC22: Beban Administrasi Kredit - LC/SKBDN | LE22: Jumlah Beban Diluar Usaha | LG22: PAJAK PENGHASILAN | LH22: Beban Pajak Penghasilan | LI22: Jumlah Pajak Penghasilan | LJ22: Jumlah Beban | LK22: EBITDA
A23: January | B23: 22271442059 | C23: 14550282537 | D23: 7721159523 | F23: 2797455742 | G23: 689993629 | H23: 85297200 | I23: 3572746571 | J23: 4148412952 | L23: 14972802 | M23: 2000053969 | N23: -1985081168 | P23: 2163331785 | Q23: 818660 | S23: 818660 | T23: 2162513125 | W23: - | X23: 2162513125 | AD23: 44214340653 | AE23: 44331095704 | AG23: -325897486 | AH23: 10333743154 | AI23: 104300563162 | AJ23: - | AL23: 27470911203 | AM23: 12165949131 | AN23: 242490705521 | AP23: - | AQ23: 127315422381 | AR23: 6707849388 | AU23: 1712002768 | AV23: 135735274537 | AW23: 378225980058 | BA23: 21736710978 | BC23: - | BD23: - | BE23: 5705977764 | BF23: 9760447198 | BI23: 145767226 | BJ23: - | BK23: 198250150994 | BL23: 235599054161 | BN23: 10372247233 | BO23: - | BQ23: 5424840824 | BR23: - | BS23: 15797088057 | BT23: 251396142218 | BV23: 68245000000 | BW23: - | BX23: 2162513125 | BY23: 53985061075 | BZ23: -541805960 | CA23: - | CB23: 2979069600 | CC23: 126829837839 | CD23: 378225980058 | CF23: January | DQ23: January | DR23: 22321496113 | DT23: -49804054 | DU23: -250000 | DV23: 22271442059 | DZ23: 11233807019 | EA23: 419236000 | EE23: 222361613 | EF23: 175478 | EG23: 3802702 | EH23: 3154533 | EI23: 19358144 | EJ23: 328037 | EK23: 3330313 | EL23: 99249577 | EM23: 36077806 | EO23: 60150000 | EP23: 9103283 | ER23: 326841928 | ES23: 59495840 | ET23: 1256104694 | EV23: 527050 | EY23: 73522457 | EZ23: 161256537 | FA23: 10059662 | FC23: 78314507 | FD23: 22316357 | FF23: 5981156 | FG23: 214800 | FI23: 12000000 | FJ23: 22472770 | FO23: 13196810 | FR23: 117593000 | FV23: 53400200 | FW23: 23953018 | FZ23: 83382614 | GA23: 56657612 | GB23: 14957210 | GC23: 7356377 | GD23: 315543 | GE23: 15133876 | GF23: 437015 | GG23: 24510000 | GH23: 147000 | GM23: 14550282537 | GQ23: 33272500 | GR23: 59048061 | GS23: 155000 | GT23: 23945243 | GU23: 82255996 | GV23: 47123961 | GW23: 22118501 | GX23: 229723827 | GY23: 403465056 | GZ23: 453491678 | HC23: 40204681 | HG23: 29664522 | HH23: 61503254 | HI23: 225000 | HJ23: 48106641 | HK23: 712553 | HN23: 2502709 | HO23: 28181917 | HP23: 5290000 | HQ23: 116650988 | HR23: 8832900 | HT23: 54003207 | HU23: 59550000 | HV23: 49160000 | HX23: 124627563 | HY23: 1996000 | HZ23: 7520728 | IA23: 2529592 | IB23: 3316499 | IC23: 20354381 | ID23: 16661730 | IE23: 17158107 | IF23: 3178477 | IG23: 18466200 | IM23: 77824374 | IQ23: 380000 | JB23: 80200000 | JH23: 7339144 | JM23: 420042284 | JN23: 46928088 | JO23: 765000 | JP23: 41576967 | JQ23: 28962413 | JS23: 16440000 | JT23: 2797455742 | JW23: 491945849 | JX23: 147499000 | JY23: 50548780 | JZ23: 689993629 | KC23: 85297200 | KD23: 85297200 | KG23: 9971413 | KK23: 1389 | KN23: 14972802 | KQ23: 10483936 | KR23: 1612378407 | KT23: 103409480 | KV23: 217846340 | KW23: 2175 | LC23: 5933631 | LE23: 2000053970 | LH23: 818660 | LI23: 818660 | LJ23: =LE23+KD23+JZ23+JT23 -> 5572800541
A24: February | B24: 62193098489 | C24: 41995808416 | D24: 20197290073 | F24: 5948337818 | G24: 1634181348 | H24: 90764202 | I24: 7673283368 | J24: 12524006705 | L24: 366817240 | M24: 4923618479 | N24: -4556801239 | P24: 7967205467 | Q24: 939175 | S24: 939175 | T24: 7966266292 | W24: - | X24: 7966266292 | AD24: 20099667310 | AE24: 49863908492 | AG24: -325897486 | AH24: 10184417154 | AI24: 119522871582 | AJ24: - | AL24: 9744087704 | AM24: 16589488907 | AN24: 225678543663 | AP24: - | AQ24: 130348634297 | AR24: 6678391743 | AU24: 1712002768 | AV24: 138739028808 | AW24: 364417572471 | BA24: 15356991892 | BC24: - | BD24: - | BE24: 8435842992 | BF24: 8132536607 | BI24: 211412619 | BJ24: - | BK24: 178095094338 | BL24: 210231878448 | BN24: 16131668617 | BO24: - | BP24: 5420434399 | BQ24: - | BR24: 21552103016 | BS24: 231783981464 | BU24: 68245000000 | BV24: - | BW24: 7966266292 | BX24: 53985061075 | BY24: -541805960 | BZ24: - | CB24: 2979069600 | CC24: 132633591006 | CD24: 364417572471 | CF24: February | DQ24: February | DR24: 62337414430 | DT24: -144065941 | DU24: -250000 | DV24: 62193098489 | DZ24: 41995808416 | EA24: 984727000 | EE24: 444366975 | EF24: 1468944 | EG24: 6499650 | EH24: 12204311 | EI24: 21320922 | EJ24: 913916 | EK24: 3481852 | EL24: 105887437 | EM24: 72447560 | EO24: 136350000 | EP24: 20344703 | ER24: 690949354 | ES24: 531012409 | ET24: 3253296089 | EV24: 7497538 | EX24: 7791915 | EY24: 158264647 | EZ24: 348391323 | FA24: 40710236 | FC24: 192766711 | FD24: 44298816 | FF24: 26178595 | FG24: 299178 | FI24: 36380000 | FJ24: 57697900 | FO24: 41148912 | FQ24: 82347618 | FR24: 302085750 | FW24: 48453550 | FZ24: 87869514 | GA24: 76031417 | GB24: 24164940 | GC24: 8557462 | GD24: 12672832 | GE24: 46363537 | GF24: 1542886 | GG24: 24510000 | GH24: 21097373 | GI24: 250000000 | GM24: 4.1995806e+10 | GQ24: 37272500 | GR24: 115729122 | GS24: 155000 | GT24: 42859243 | GU24: 164511991 | GV24: 95596203 | GW24: 44237002 | GX24: 459447655 | GY24: 885124224 | GZ24: 1030289227 | HC24: 80340812 | HG24: 62633056 | HH24: 118241036 | HI24: 225000 | HJ24: 85202799 | HK24: 8493578 | HN24: 5005418 | HO24: 63671763 | HP24: 9974000 | HQ24: 330978204 | HR24: 30367550 | HS24: 3231689 | HT24: 115825581 | HU24: 75150000 | HV24: 49949750 | HW24: 112500000 | HX24: 215958517 | HY24: 11329482 | HZ24: 14092878 | IA24: 9903242 | IB24: 5751498 | IC24: 36150492 | ID24: 45552367 | IE24: 27439117 | IF24: 8383938 | IG24: 27952425 | IH24: 4550000 | IK24: 17500000 | IL24: 545613 | IM24: 179261372 | IO24: 500000 | IQ24: 540000 | IU24: 10256410 | JB24: 90200000 | JE24: 1100000 | JH24: 14678288 | JI24: 5780000 | JK24: 27600000 | JM24: 919791824 | JN24: 74485026 | JO24: 7067090 | JP24: 84438423 | JQ24: 34662413 | JR24: 4500000 | JS24: 41355000 | JT24: 594833781800 | JW24: 1333255924 | JX24: 192795000 | JY24: 108130424000000 | JZ24: 1634181348 | KC24: 90764202 | KD24: 90764202 | KG24: 20373845 | KH24: 12524000 | KI24: 328712547 | KJ24: 250000 | KK24: 1893 | KM24: 4954955 | KN24: 366817240 | KQ24: 19597654 | KR24: 3347966924 | KT24: 197076142 | KV24: 849340071 | KW24: 4056 | KZ24: 500000000 | LC24: 9633631 | LE24: 4923618479 | LH24: 939175 | LI24: 939175 | LJ24: =LE24+KD24+JZ24+JT24 -> 601482345829
A25: March | B25: 110370489515 | C25: 82906707994 | D25: 27463781520 | F25: 9208484937 | G25: 2948396212 | H25: 128485815 | I25: 12285366964 | J25: 15178414556 | L25: 537194857 | M25: 7100569924 | N25: -6563375067 | P25: 8615039489 | Q25: 939175 | S25: 939175 | T25: 8614100314 | W25: - | X25: 8614100314 | AD25: 19442003776 | AE25: 51173068869 | AG25: -325897486 | AH25: 10482259154 | AI25: 92350283616 | AJ25: - | AL25: 20785426853 | AM25: 12225997754 | AN25: 206133142535 | AP25: - | AQ25: 130908524708 | AR25: 6648934098 | AU25: 1712002768 | AV25: 139269461574 | AW25: 345402604109 | BA25: 12535565229 | BC25: - | BD25: - | BE25: 5495911745 | BF25: 1887033524 | BI25: 123728456 | BJ25: - | BK25: 171105117438 | BL25: 191147356392 | BN25: 16098725935 | BO25: - | BP25: - | BQ25: 4874363998 | BR25: - | BS25: 20973089933 | BT25: 212120446325 | BV25: 68245000000 | BW25: - | BX25: 8614100314 | BY25: 53985793831 | BZ25: -541805960 | CA25: - | CB25: 2979069600 | CC25: 133282157785 | CD25: 345402604110 | CF25: March | DQ25: March | DR25: 110519521998 | DT25: -145181940 | DU25: -3850543 | DV25: 110370489515 | DZ25: 70532863645 | EA25: 1016185000 | EE25: 659809838 | EF25: 1468944 | EG25: 11630050 | EH25: 12602663 | EI25: 24951552 | EJ25: 6424414 | EK25: 3481852 | EL25: 114942535 | EM25: 108881429 | EO25: 214750000 | EP25: 17922319 | ER25: 1021398046 | ES25: 1094839512 | ET25: 4782070414 | EV25: 32718697 | EX25: 21091913 | EY25: 235420730 | EZ25: 518560400 | FA25: 44483446 | FC25: 350376716 | FD25: 67014624 | FF25: 58858966 | FG25: 345003 | FI25: 49580000 | FJ25: 78345975 | FO25: 60195162 | FQ25: 156211275 | FR25: 421789940 | FV25: 145135445 | FW25: 234336533 | FX25: 6500000 | FZ25: 90554264 | GA25: 148034771 | GB25: 29641658 | GC25: 8782374 | GD25: 13801961 | GE25: 193635646 | GF25: 3413220 | GG25: 24510000 | GH25: 36408877 | GI25: 250000000 | GJ25: 2738184 | GM25: 82906707994 | GQ25: 37461300 | GR25: 172410183 | GS25: 2210234 | GT25: 65435507 | GU25: 237840430 | GV25: 144000870 | GW25: 66355503 | GX25: 689171482 | GY25: 1330845744 | GZ25: 1531631022 | HC25: 122201428 | HF25: 235397436 | HG25: 93925171 | HH25: 176825817 | HI25: 795000 | HJ25: 115260225 | HK25: 48552081 | HN25: 7508127 | HO25: 93040877 | HP25: 12618500 | HQ25: 723247172 | HR25: 48622550 | HS25: 3702889 | HT25: 155566314 | HU25: 112600000 | HV25: 49949750 | HW25: 112500000 | HX25: 230143017 | HY25: 14012855 | HZ25: 27159774 | IA25: 11568842 | IB25: 6210498 | IC25: 60213267 | ID25: 73938932 | IE25: 38703585 | IF25: 13046163 | IG25: 48561425 | IH25: 7550000 | IK25: 17500000 | IL25: 1682333 | IM25: 324478732 | IO25: 500000 | IQ25: 540000 | IT25: 3153153 | IU25: 10256410 | JB25: 102350000 | JE25: 1100000 | JH25: 22017432 | JI25: 5780000 | JK25: 27600000 | JM25: 1368212321 | JN25: 113957469000000 | JO25: 16510400 | JP25: 130318007 | JQ25: 78787210 | JR25: 13500000 | JS25: 49457500 | JT25: 9208484937 | JW25: 2446110330 | JX25: 336795000 | JY25: 165490882 | JZ25: 2948396212 | KC25: 128485815 | KD25: 128485815 | KG25: 30903520 | KH25: 18758595 | KI25: 480936493 | KJ25: 250000 | KK25: 2493 | KM25: 6343756 | KN25: 537194857 | KQ25: 28911800 | KR25: 4970896952 | KT25: 290742804 | KV25: 849340071 | KW25: 644259 | KY25: 400407 | KZ25: 950000000 | LC25: 9633631 | LE25: 7100569924 | LH25: 939175 | LI25: 939175 | LJ25: =LE25+KD25+JZ25+JT25 -> 19385936888
A26: April | B26: 139947620196 | C26: 105088851349 | D26: 34858768846 | F26: 12950979758 | G26: 3461167848 | H26: 174461315 | I26: 16586608921 | J26: 18272159926 | L26: 1001810395 | M26: 9437715037 | N26: -8435904642 | P26: 9836255284 | Q26: 7885483 | S26: 7885483 | T26: 9828369801 | W26: - | X26: 9828369801 | AD26: 22149448688 | AE26: 39387620234 | AG26: -726809713 | AH26: 8069303618 | AI26: 99484397378 | AJ26: - | AL26: 42184427546 | AM26: 13027126905 | AN26: 223575514655 | AP26: - | AQ26: 130729959005 | AR26: 7117825212 | AU26: 3097471000 | AV26: 140945255216 | AW26: 364520769872 | BA26: 13754261151 | BC26: - | BD26: - | BE26: 5190026785 | BF26: 2875451223 | BI26: 204767964 | BJ26: - | BK26: 186931451312 | BL26: 208955958435 | BN26: 15378310047 | BQ26: 10699500880 | BR26: - | BS26: 26077810927 | BT26: 235033769362 | BV26: 68245000000 | BW26: - | BX26: 9828369801 | BY26: 50176612716 | BZ26: -3110625307 | CA26: - | CB26: 4347643300 | CC26: 129487000509 | CD26: 364520769872 | CF26: April | DQ26: April | DR26: 140133396985 | DT26: -148252159 | DU26: -37524630 | DV26: 139947620196 | DZ26: 88927651287 | EA26: 1249743000 | EE26: 922887414 | EF26: 3305634 | EG26: 14111742 | EH26: 20328456 | EI26: 25830794 | EJ26: 6736668 | EK26: 3510698 | EL26: 119013891 | EM26: 144511933 | EO26: 264450000 | EP26: -1904413 | ER26: 1345683530 | ES26: 1402110444 | ET26: 6306811771 | EV26: 41716197 | EX26: 40603290 | EY26: 312904213 | EZ26: 675087980 | FA26: 52303376 | FC26: 428452015 | FD26: 87167963 | FF26: 59543286 | FG26: 2631125 | FI26: 86060000 | FJ26: 109564925 | FN26: 660000 | FO26: 81430327 | FQ26: 161402770 | FR26: 688805339 | FV26: 168540445 | FW26: 234336533 | FX26: 22355186 | FZ26: 121754264 | GA26: 200397475 | GB26: 34442645 | GC26: 18328113 | GD26: 9303274 | GE26: 215272754 | GF26: 6784749 | GG26: 27610000 | GH26: 36553387 | GI26: 250000000 | GJ26: 4217246 | GK26: 155839622 | GM26: 105088851349 | GQ26: 87856300 | GR26: 229091244 | GS26: 3307053 | GT26: 102276175 | GU26: 311168869 | GV26: 192072026 | GW26: 88474004 | GX26: 918895310 | GY26: 1706087228 | GZ26: 2023904146 | HC26: 154333880 | HF26: 422380511 | HG26: 125693376 | HH26: 234667747 | HI26: 795000 | HJ26: 124232921 | HK26: 50424034 | HN26: 10010836 | HO26: 133737419 | HP26: 19196100 | HQ26: 1091015012 | HR26: 56039550 | HS26: 5797889 | HT26: 409802895 | HU26: 115200000 | HV26: 49949750 | HW26: 112500000 | HX26: 253809772 | HY26: 26365895 | HZ26: 47276760 | IA26: 25448300 | IB26: 8703998 | IC26: 88033174 | ID26: 116586859 | IE26: 48921115 | IF26: 16304142 | IG26: 63316656 | IH26: 14400801 | IK26: 17500000 | IL26: 1682333 | IM26: 469276915 | IN26: 249716382 | IO26: 500000 | IP26: 100201552 | IQ26: 540000 | IS26: 20512326 | IT26: 17806306 | IU26: 10256410 | IX26: 17975000 | JB26: 108272000 | JE26: 1430309 | JH26: 29356576000000 | JI26: 5780000 | JK26: 34775000 | JM26: 1885604221 | JN26: 113957469 | JO26: 18637911000000 | JP26: 171220924 | JQ26: 89203876 | JR26: 18000000 | JS26: 80697500 | JT26: 12950979758 | JW26: 2869719284 | JX26: 357795000000000 | JY26: 233653564 | JZ26: 3461167848 | KC26: 174461315 | KD26: 174461315 | KG26: 45865998 | KH26: 24688500 | KI26: 924046182 | KJ26: 2250000 | KK26: 4760 | KM26: 6343756 | KN26: 1001810395 | KQ26: 40254666 | KR26: 6637253505 | KT26: 390112436 | KV26: 849340071 | KW26: 109093 | KX26: 11011635 | KZ26: 1500000000 | LC26: 9633631 | LE26: 9437715037 | LH26: 7885483 | LI26: 7885483 | LJ26: =LE26+KD26+JZ26+JT26 -> 26024323958
